Workbook

Sheet Asistencia
A1: LISTA DE ASISTENCIA — ARQUITECTURA DE SISTEMAS DE SEGURIDAD | Ciclo 2026-A | CRN 236396 | Sección 401 | Aula 101 Edif. 4L
A2: CUGDL · UDG | Licenciatura en Ciberseguridad | 19 Enero – 29 Mayo 2026 | Horario: L 07:00-08:55 Mi 09:00-10:55 | Prof. Titular: Luis Alberto Maciel Arellano | Prof. Suplente: Carlos Pulido Rosas | Total sesiones válidas: 32
A3: # | B3: APELLIDO(S) | C3: NOMBRE(S) | D3: CÓDIGO | E3: Puntos Extra Participación | F3: Puntos Extra Examen | G3: SEM 1 | I3: SEM 2 | K3: SEM 3 | M3: SEM 4 | O3: SEM 5 | Q3: SEM 6 | S3: SEM 7 | U3: SEM 8 | W3: SEM 9 | Y3: SEM 10 | AA3: SEM 11 | AC3: SEM 12 | AE3: SEM 13 | AG3: SEM 14 | AI3: SEM 15 | AK3: SEM 16 | AM3: ASIST. | AN3: FALTAS | AO3: % ASIST.
G4: L | H4: Mi | I4: L | J4: Mi | K4: L | L4: Mi | M4: L | N4: Mi | O4: L | P4: Mi | Q4: L | R4: Mi | S4: L | T4: Mi | U4: L | V4: Mi | W4: L | X4: Mi | Y4: L | Z4: Mi | AA4: L | AB4: Mi | AC4: L | AD4: Mi | AE4: L | AF4: Mi | AG4: L | AH4: Mi | AI4: L | AJ4: Mi | AK4: L | AL4: Mi
G5: 19/01 | H5: 21/01 | I5: 26/01 | J5: 28/01 | K5: 02/02 | L5: 04/02 | M5: 09/02 | N5: 11/02 | O5: 16/02 | P5: 18/02 | Q5: 23/02 | R5: 25/02 | S5: 02/03 | T5: 04/03 | U5: 09/03 | V5: 11/03 | W5: 16/03 | X5: 18/03 | Y5: 23/03 | Z5: 25/03 | AA5: 13/04 | AB5: 15/04 | AC5: 20/04 | AD5: 22/04 | AE5: 27/04 | AF5: 29/04 | AG5: 04/05 | AH5: 06/05 | AI5: 11/05 | AJ5: 13/05 | AK5: 18/05 | AL5: 20/05
A6: 1 | B6: ACOSTA SANDOVAL | C6: ROGELIO ESAU | D6: 220840099 | F6: =IFERROR(ROUND(_xlfn.XLOOKUP(B6&" "&C6,'Examen 1'!B$2:B$27,'Examen 1'!E$2:E$27,0)/100*5,1),0) -> 5 | G6: A | H6: A | I6: A | J6: A | K6: A | L6: A | M6: A | N6: A | O6: A | P6: A | Q6: A | R6: A | S6: A | T6: A | U6: A | V6: A | W6: A | X6: - | Y6: - | Z6: - | AA6: A | AB6: A | AC6: A | AD6: A | AE6: A | AM6: =COUNTIF(G6,"A")+COUNTIF(H6,"A")+COUNTIF(I6,"A")+COUNTIF(J6,"A")+COUNTIF(K6,"A")+COUNTIF(L6,"A")+COUNTIF(M6,"A")+COUNTIF(N6,"A")+COUNTIF(O6,"A")+COUNTIF(P6,"A")+COUNTIF(Q6,"A")+COUNTIF(R6,"A")+COUNTIF(S6,"A")+COUNTIF(T6,"A")+COUNTIF(U6,"A")+COUNTIF(V6,"A")+COUNTIF(W6,"A")+COUNTIF(X6,"A")+COUNTIF(Y6,"A")+COUNTIF(Z6,"A")+COUNTIF(AA6,"A")+COUNTIF(AB6,"A")+COUNTIF(AC6,"A")+COUNTIF(AD6,"A")+COUNTIF(AE6,"A")+COUNTIF(AF6,"A")+COUNTIF(AG6,"A")+COUNTIF(AH6,"A")+COUNTIF(AI6,"A")+COUNTIF(AJ6,"A")+COUNTIF(AK6,"A")+COUNTIF(AL6,"A") -> 22 | AN6: =COUNTIF(G6,"F")+COUNTIF(H6,"F")+COUNTIF(I6,"F")+COUNTIF(J6,"F")+COUNTIF(K6,"F")+COUNTIF(L6,"F")+COUNTIF(M6,"F")+COUNTIF(N6,"F")+COUNTIF(O6,"F")+COUNTIF(P6,"F")+COUNTIF(Q6,"F")+COUNTIF(R6,"F")+COUNTIF(S6,"F")+COUNTIF(T6,"F")+COUNTIF(U6,"F")+COUNTIF(V6,"F")+COUNTIF(W6,"F")+COUNTIF(X6,"F")+COUNTIF(Y6,"F")+COUNTIF(Z6,"F")+COUNTIF(AA6,"F")+COUNTIF(AB6,"F")+COUNTIF(AC6,"F")+COUNTIF(AD6,"F")+COUNTIF(AE6,"F")+COUNTIF(AF6,"F")+COUNTIF(AG6,"F")+COUNTIF(AH6,"F")+COUNTIF(AI6,"F")+COUNTIF(AJ6,"F")+COUNTIF(AK6,"F")+COUNTIF(AL6,"F") -> 0 | AO6: =IF(AM6=0,"",AM6/32) -> 0.6875
A7: 2 | B7: ARIAS CASTELLON | C7: GABRIELA ESPERA | D7: 088404858 | F7: =IFERROR(ROUND(_xlfn.XLOOKUP(B7&" "&C7,'Examen 1'!B$2:B$27,'Examen 1'!E$2:E$27,0)/100*5,1),0) -> 4.3 | G7: A | H7: A | I7: A | J7: A | K7: A | L7: A | M7: A | N7: A | O7: A | P7: A | Q7: A | R7: A | S7: A | T7: A | U7: A | V7: A | W7: A | X7: - | Y7: - | Z7: - | AA7: A | AB7: A | AC7: A | AD7: A | AE7: A | AM7: =COUNTIF(G7,"A")+COUNTIF(H7,"A")+COUNTIF(I7,"A")+COUNTIF(J7,"A")+COUNTIF(K7,"A")+COUNTIF(L7,"A")+COUNTIF(M7,"A")+COUNTIF(N7,"A")+COUNTIF(O7,"A")+COUNTIF(P7,"A")+COUNTIF(Q7,"A")+COUNTIF(R7,"A")+COUNTIF(S7,"A")+COUNTIF(T7,"A")+COUNTIF(U7,"A")+COUNTIF(V7,"A")+COUNTIF(W7,"A")+COUNTIF(X7,"A")+COUNTIF(Y7,"A")+COUNTIF(Z7,"A")+COUNTIF(AA7,"A")+COUNTIF(AB7,"A")+COUNTIF(AC7,"A")+COUNTIF(AD7,"A")+COUNTIF(AE7,"A")+COUNTIF(AF7,"A")+COUNTIF(AG7,"A")+COUNTIF(AH7,"A")+COUNTIF(AI7,"A")+COUNTIF(AJ7,"A")+COUNTIF(AK7,"A")+COUNTIF(AL7,"A") -> 22 | AN7: =COUNTIF(G7,"F")+COUNTIF(H7,"F")+COUNTIF(I7,"F")+COUNTIF(J7,"F")+COUNTIF(K7,"F")+COUNTIF(L7,"F")+COUNTIF(M7,"F")+COUNTIF(N7,"F")+COUNTIF(O7,"F")+COUNTIF(P7,"F")+COUNTIF(Q7,"F")+COUNTIF(R7,"F")+COUNTIF(S7,"F")+COUNTIF(T7,"F")+COUNTIF(U7,"F")+COUNTIF(V7,"F")+COUNTIF(W7,"F")+COUNTIF(X7,"F")+COUNTIF(Y7,"F")+COUNTIF(Z7,"F")+COUNTIF(AA7,"F")+COUNTIF(AB7,"F")+COUNTIF(AC7,"F")+COUNTIF(AD7,"F")+COUNTIF(AE7,"F")+COUNTIF(AF7,"F")+COUNTIF(AG7,"F")+COUNTIF(AH7,"F")+COUNTIF(AI7,"F")+COUNTIF(AJ7,"F")+COUNTIF(AK7,"F")+COUNTIF(AL7,"F") -> 0 | AO7: =IF(AM7=0,"",AM7/32) -> 0.6875
A8: 3 | B8: AVALOS RODRIGUEZ | C8: KAROL GUADALUPE | D8: 224164552 | E8: 1 | F8: =IFERROR(ROUND(_xlfn.XLOOKUP(B8&" "&C8,'Examen 1'!B$2:B$27,'Examen 1'!E$2:E$27,0)/100*5,1),0) -> 3.3 | G8: A | H8: A | I8: A | J8: A | K8: A | L8: A | M8: A | N8: A | O8: A | P8: A | Q8: A | R8: A | S8: A | T8: A | U8: A | V8: A | W8: A | X8: - | Y8: - | Z8: - | AA8: A | AB8: A | AC8: A | AD8: A | AE8: A | AM8: =COUNTIF(G8,"A")+COUNTIF(H8,"A")+COUNTIF(I8,"A")+COUNTIF(J8,"A")+COUNTIF(K8,"A")+COUNTIF(L8,"A")+COUNTIF(M8,"A")+COUNTIF(N8,"A")+COUNTIF(O8,"A")+COUNTIF(P8,"A")+COUNTIF(Q8,"A")+COUNTIF(R8,"A")+COUNTIF(S8,"A")+COUNTIF(T8,"A")+COUNTIF(U8,"A")+COUNTIF(V8,"A")+COUNTIF(W8,"A")+COUNTIF(X8,"A")+COUNTIF(Y8,"A")+COUNTIF(Z8,"A")+COUNTIF(AA8,"A")+COUNTIF(AB8,"A")+COUNTIF(AC8,"A")+COUNTIF(AD8,"A")+COUNTIF(AE8,"A")+COUNTIF(AF8,"A")+COUNTIF(AG8,"A")+COUNTIF(AH8,"A")+COUNTIF(AI8,"A")+COUNTIF(AJ8,"A")+COUNTIF(AK8,"A")+COUNTIF(AL8,"A") -> 22 | AN8: =COUNTIF(G8,"F")+COUNTIF(H8,"F")+COUNTIF(I8,"F")+COUNTIF(J8,"F")+COUNTIF(K8,"F")+COUNTIF(L8,"F")+COUNTIF(M8,"F")+COUNTIF(N8,"F")+COUNTIF(O8,"F")+COUNTIF(P8,"F")+COUNTIF(Q8,"F")+COUNTIF(R8,"F")+COUNTIF(S8,"F")+COUNTIF(T8,"F")+COUNTIF(U8,"F")+COUNTIF(V8,"F")+COUNTIF(W8,"F")+COUNTIF(X8,"F")+COUNTIF(Y8,"F")+COUNTIF(Z8,"F")+COUNTIF(AA8,"F")+COUNTIF(AB8,"F")+COUNTIF(AC8,"F")+COUNTIF(AD8,"F")+COUNTIF(AE8,"F")+COUNTIF(AF8,"F")+COUNTIF(AG8,"F")+COUNTIF(AH8,"F")+COUNTIF(AI8,"F")+COUNTIF(AJ8,"F")+COUNTIF(AK8,"F")+COUNTIF(AL8,"F") -> 0 | AO8: =IF(AM8=0,"",AM8/32) -> 0.6875
A9: 4 | B9: CARCAÑO AGUAYO | C9: ANDREA LISSETH | D9: 221449008 | F9: =IFERROR(ROUND(_xlfn.XLOOKUP(B9&" "&C9,'Examen 1'!B$2:B$27,'Examen 1'!E$2:E$27,0)/100*5,1),0) -> 5 | G9: A | H9: A | I9: A | J9: A | K9: A | L9: A | M9: A | N9: A | O9: A | P9: A | Q9: A | R9: A | S9: A | T9: A | U9: A | V9: A | W9: A | X9: - | Y9: - | Z9: - | AA9: A | AB9: A | AC9: A | AD9: A | AE9: A | AM9: =COUNTIF(G9,"A")+COUNTIF(H9,"A")+COUNTIF(I9,"A")+COUNTIF(J9,"A")+COUNTIF(K9,"A")+COUNTIF(L9,"A")+COUNTIF(M9,"A")+COUNTIF(N9,"A")+COUNTIF(O9,"A")+COUNTIF(P9,"A")+COUNTIF(Q9,"A")+COUNTIF(R9,"A")+COUNTIF(S9,"A")+COUNTIF(T9,"A")+COUNTIF(U9,"A")+COUNTIF(V9,"A")+COUNTIF(W9,"A")+COUNTIF(X9,"A")+COUNTIF(Y9,"A")+COUNTIF(Z9,"A")+COUNTIF(AA9,"A")+COUNTIF(AB9,"A")+COUNTIF(AC9,"A")+COUNTIF(AD9,"A")+COUNTIF(AE9,"A")+COUNTIF(AF9,"A")+COUNTIF(AG9,"A")+COUNTIF(AH9,"A")+COUNTIF(AI9,"A")+COUNTIF(AJ9,"A")+COUNTIF(AK9,"A")+COUNTIF(AL9,"A") -> 22 | AN9: =COUNTIF(G9,"F")+COUNTIF(H9,"F")+COUNTIF(I9,"F")+COUNTIF(J9,"F")+COUNTIF(K9,"F")+COUNTIF(L9,"F")+COUNTIF(M9,"F")+COUNTIF(N9,"F")+COUNTIF(O9,"F")+COUNTIF(P9,"F")+COUNTIF(Q9,"F")+COUNTIF(R9,"F")+COUNTIF(S9,"F")+COUNTIF(T9,"F")+COUNTIF(U9,"F")+COUNTIF(V9,"F")+COUNTIF(W9,"F")+COUNTIF(X9,"F")+COUNTIF(Y9,"F")+COUNTIF(Z9,"F")+COUNTIF(AA9,"F")+COUNTIF(AB9,"F")+COUNTIF(AC9,"F")+COUNTIF(AD9,"F")+COUNTIF(AE9,"F")+COUNTIF(AF9,"F")+COUNTIF(AG9,"F")+COUNTIF(AH9,"F")+COUNTIF(AI9,"F")+COUNTIF(AJ9,"F")+COUNTIF(AK9,"F")+COUNTIF(AL9,"F") -> 0 | AO9: =IF(AM9=0,"",AM9/32) -> 0.6875
A10: 5 | B10: DE LA VEGA SANCHEZ | C10: ISIS KAROL | D10: 221450537 | E10: 1.5 | F10: =IFERROR(ROUND(_xlfn.XLOOKUP(B10&" "&C10,'Examen 1'!B$2:B$27,'Examen 1'!E$2:E$27,0)/100*5,1),0) -> 4.3 | G10: A | H10: A | I10: A | J10: A | K10: A | L10: A | M10: A | N10: A | O10: A | P10: A | Q10: A | R10: A | S10: A | T10: A | U10: A | V10: A | W10: A | X10: - | Y10: - | Z10: - | AA10: A | AB10: A | AC10: A | AD10: A | AE10: A | AM10: =COUNTIF(G10,"A")+COUNTIF(H10,"A")+COUNTIF(I10,"A")+COUNTIF(J10,"A")+COUNTIF(K10,"A")+COUNTIF(L10,"A")+COUNTIF(M10,"A")+COUNTIF(N10,"A")+COUNTIF(O10,"A")+COUNTIF(P10,"A")+COUNTIF(Q10,"A")+COUNTIF(R10,"A")+COUNTIF(S10,"A")+COUNTIF(T10,"A")+COUNTIF(U10,"A")+COUNTIF(V10,"A")+COUNTIF(W10,"A")+COUNTIF(X10,"A")+COUNTIF(Y10,"A")+COUNTIF(Z10,"A")+COUNTIF(AA10,"A")+COUNTIF(AB10,"A")+COUNTIF(AC10,"A")+COUNTIF(AD10,"A")+COUNTIF(AE10,"A")+COUNTIF(AF10,"A")+COUNTIF(AG10,"A")+COUNTIF(AH10,"A")+COUNTIF(AI10,"A")+COUNTIF(AJ10,"A")+COUNTIF(AK10,"A")+COUNTIF(AL10,"A") -> 22 | AN10: =COUNTIF(G10,"F")+COUNTIF(H10,"F")+COUNTIF(I10,"F")+COUNTIF(J10,"F")+COUNTIF(K10,"F")+COUNTIF(L10,"F")+COUNTIF(M10,"F")+COUNTIF(N10,"F")+COUNTIF(O10,"F")+COUNTIF(P10,"F")+COUNTIF(Q10,"F")+COUNTIF(R10,"F")+COUNTIF(S10,"F")+COUNTIF(T10,"F")+COUNTIF(U10,"F")+COUNTIF(V10,"F")+COUNTIF(W10,"F")+COUNTIF(X10,"F")+COUNTIF(Y10,"F")+COUNTIF(Z10,"F")+COUNTIF(AA10,"F")+COUNTIF(AB10,"F")+COUNTIF(AC10,"F")+COUNTIF(AD10,"F")+COUNTIF(AE10,"F")+COUNTIF(AF10,"F")+COUNTIF(AG10,"F")+COUNTIF(AH10,"F")+COUNTIF(AI10,"F")+COUNTIF(AJ10,"F")+COUNTIF(AK10,"F")+COUNTIF(AL10,"F") -> 0 | AO10: =IF(AM10=0,"",AM10/32) -> 0.6875
A11: 6 | B11: DE LUNA MOZQUEDA | C11: EMMANUEL | D11: 209015442 | F11: =IFERROR(ROUND(_xlfn.XLOOKUP(B11&" "&C11,'Examen 1'!B$2:B$28,'Examen 1'!E$2:E$28,0)/100*5,1),0) -> 5 | G11: A | H11: A | I11: A | J11: A | K11: A | L11: A | M11: A | N11: A | O11: A | P11: A | Q11: A | R11: A | S11: A | T11: A | U11: A | V11: A | W11: A | X11: - | Y11: - | Z11: - | AA11: A | AB11: A | AC11: A | AD11: A | AE11: A | AM11: =COUNTIF(G11,"A")+COUNTIF(H11,"A")+COUNTIF(I11,"A")+COUNTIF(J11,"A")+COUNTIF(K11,"A")+COUNTIF(L11,"A")+COUNTIF(M11,"A")+COUNTIF(N11,"A")+COUNTIF(O11,"A")+COUNTIF(P11,"A")+COUNTIF(Q11,"A")+COUNTIF(R11,"A")+COUNTIF(S11,"A")+COUNTIF(T11,"A")+COUNTIF(U11,"A")+COUNTIF(V11,"A")+COUNTIF(W11,"A")+COUNTIF(X11,"A")+COUNTIF(Y11,"A")+COUNTIF(Z11,"A")+COUNTIF(AA11,"A")+COUNTIF(AB11,"A")+COUNTIF(AC11,"A")+COUNTIF(AD11,"A")+COUNTIF(AE11,"A")+COUNTIF(AF11,"A")+COUNTIF(AG11,"A")+COUNTIF(AH11,"A")+COUNTIF(AI11,"A")+COUNTIF(AJ11,"A")+COUNTIF(AK11,"A")+COUNTIF(AL11,"A") -> 22 | AN11: =COUNTIF(G11,"F")+COUNTIF(H11,"F")+COUNTIF(I11,"F")+COUNTIF(J11,"F")+COUNTIF(K11,"F")+COUNTIF(L11,"F")+COUNTIF(M11,"F")+COUNTIF(N11,"F")+COUNTIF(O11,"F")+COUNTIF(P11,"F")+COUNTIF(Q11,"F")+COUNTIF(R11,"F")+COUNTIF(S11,"F")+COUNTIF(T11,"F")+COUNTIF(U11,"F")+COUNTIF(V11,"F")+COUNTIF(W11,"F")+COUNTIF(X11,"F")+COUNTIF(Y11,"F")+COUNTIF(Z11,"F")+COUNTIF(AA11,"F")+COUNTIF(AB11,"F")+COUNTIF(AC11,"F")+COUNTIF(AD11,"F")+COUNTIF(AE11,"F")+COUNTIF(AF11,"F")+COUNTIF(AG11,"F")+COUNTIF(AH11,"F")+COUNTIF(AI11,"F")+COUNTIF(AJ11,"F")+COUNTIF(AK11,"F")+COUNTIF(AL11,"F") -> 0 | AO11: =IF(AM11=0,"",AM11/32) -> 0.6875
A12: 7 | B12: FRANCO ARELLANO | C12: DAPHNE WENDOLYN | D12: 219051455 | E12: 1 | F12: =IFERROR(ROUND(_xlfn.XLOOKUP(B12&" "&C12,'Examen 1'!B$2:B$27,'Examen 1'!E$2:E$27,0)/100*5,1),0) -> 5 | G12: A | H12: A | I12: A | J12: A | K12: A | L12: A | M12: A | N12: A | O12: A | P12: A | Q12: A | R12: A | S12: A | T12: A | U12: A | V12: A | W12: A | X12: - | Y12: - | Z12: - | AA12: A | AB12: A | AC12: A | AD12: A | AE12: A | AM12: =COUNTIF(G12,"A")+COUNTIF(H12,"A")+COUNTIF(I12,"A")+COUNTIF(J12,"A")+COUNTIF(K12,"A")+COUNTIF(L12,"A")+COUNTIF(M12,"A")+COUNTIF(N12,"A")+COUNTIF(O12,"A")+COUNTIF(P12,"A")+COUNTIF(Q12,"A")+COUNTIF(R12,"A")+COUNTIF(S12,"A")+COUNTIF(T12,"A")+COUNTIF(U12,"A")+COUNTIF(V12,"A")+COUNTIF(W12,"A")+COUNTIF(X12,"A")+COUNTIF(Y12,"A")+COUNTIF(Z12,"A")+COUNTIF(AA12,"A")+COUNTIF(AB12,"A")+COUNTIF(AC12,"A")+COUNTIF(AD12,"A")+COUNTIF(AE12,"A")+COUNTIF(AF12,"A")+COUNTIF(AG12,"A")+COUNTIF(AH12,"A")+COUNTIF(AI12,"A")+COUNTIF(AJ12,"A")+COUNTIF(AK12,"A")+COUNTIF(AL12,"A") -> 22 | AN12: =COUNTIF(G12,"F")+COUNTIF(H12,"F")+COUNTIF(I12,"F")+COUNTIF(J12,"F")+COUNTIF(K12,"F")+COUNTIF(L12,"F")+COUNTIF(M12,"F")+COUNTIF(N12,"F")+COUNTIF(O12,"F")+COUNTIF(P12,"F")+COUNTIF(Q12,"F")+COUNTIF(R12,"F")+COUNTIF(S12,"F")+COUNTIF(T12,"F")+COUNTIF(U12,"F")+COUNTIF(V12,"F")+COUNTIF(W12,"F")+COUNTIF(X12,"F")+COUNTIF(Y12,"F")+COUNTIF(Z12,"F")+COUNTIF(AA12,"F")+COUNTIF(AB12,"F")+COUNTIF(AC12,"F")+COUNTIF(AD12,"F")+COUNTIF(AE12,"F")+COUNTIF(AF12,"F")+COUNTIF(AG12,"F")+COUNTIF(AH12,"F")+COUNTIF(AI12,"F")+COUNTIF(AJ12,"F")+COUNTIF(AK12,"F")+COUNTIF(AL12,"F") -> 0 | AO12: =IF(AM12=0,"",AM12/32) -> 0.6875
A13: 8 | B13: FREGOSO SANCHEZ | C13: PAOLA | D13: 216592013 | F13: =IFERROR(ROUND(_xlfn.XLOOKUP(B13&" "&C13,'Examen 1'!B$2:B$27,'Examen 1'!E$2:E$27,0)/100*5,1),0) -> 4.4 | G13: A | H13: A | I13: A | J13: A | K13: A | L13: A | M13: A | N13: A | O13: A | P13: A | Q13: A | R13: A | S13: A | T13: A | U13: A | V13: A | W13: A | X13: - | Y13: - | Z13: - | AA13: A | AB13: A | AC13: A | AD13: A | AE13: A | AM13: =COUNTIF(G13,"A")+COUNTIF(H13,"A")+COUNTIF(I13,"A")+COUNTIF(J13,"A")+COUNTIF(K13,"A")+COUNTIF(L13,"A")+COUNTIF(M13,"A")+COUNTIF(N13,"A")+COUNTIF(O13,"A")+COUNTIF(P13,"A")+COUNTIF(Q13,"A")+COUNTIF(R13,"A")+COUNTIF(S13,"A")+COUNTIF(T13,"A")+COUNTIF(U13,"A")+COUNTIF(V13,"A")+COUNTIF(W13,"A")+COUNTIF(X13,"A")+COUNTIF(Y13,"A")+COUNTIF(Z13,"A")+COUNTIF(AA13,"A")+COUNTIF(AB13,"A")+COUNTIF(AC13,"A")+COUNTIF(AD13,"A")+COUNTIF(AE13,"A")+COUNTIF(AF13,"A")+COUNTIF(AG13,"A")+COUNTIF(AH13,"A")+COUNTIF(AI13,"A")+COUNTIF(AJ13,"A")+COUNTIF(AK13,"A")+COUNTIF(AL13,"A") -> 22 | AN13: =COUNTIF(G13,"F")+COUNTIF(H13,"F")+COUNTIF(I13,"F")+COUNTIF(J13,"F")+COUNTIF(K13,"F")+COUNTIF(L13,"F")+COUNTIF(M13,"F")+COUNTIF(N13,"F")+COUNTIF(O13,"F")+COUNTIF(P13,"F")+COUNTIF(Q13,"F")+COUNTIF(R13,"F")+COUNTIF(S13,"F")+COUNTIF(T13,"F")+COUNTIF(U13,"F")+COUNTIF(V13,"F")+COUNTIF(W13,"F")+COUNTIF(X13,"F")+COUNTIF(Y13,"F")+COUNTIF(Z13,"F")+COUNTIF(AA13,"F")+COUNTIF(AB13,"F")+COUNTIF(AC13,"F")+COUNTIF(AD13,"F")+COUNTIF(AE13,"F")+COUNTIF(AF13,"F")+COUNTIF(AG13,"F")+COUNTIF(AH13,"F")+COUNTIF(AI13,"F")+COUNTIF(AJ13,"F")+COUNTIF(AK13,"F")+COUNTIF(AL13,"F") -> 0 | AO13: =IF(AM13=0,"",AM13/32) -> 0.6875
A14: 9 | B14: GARAY GUZMAN | C14: CRISTIAN RENE | D14: 220105445 | F14: =IFERROR(ROUND(_xlfn.XLOOKUP(B14&" "&C14,'Examen 1'!B$2:B$27,'Examen 1'!E$2:E$27,0)/100*5,1),0) -> 5 | G14: A | H14: A | I14: A | J14: A | K14: A | L14: A | M14: A | N14: A | O14: A | P14: A | Q14: A | R14: A | S14: A | T14: A | U14: A | V14: A | W14: A | X14: - | Y14: - | Z14: - | AA14: A | AB14: A | AC14: A | AD14: A | AE14: A | AM14: =COUNTIF(G14,"A")+COUNTIF(H14,"A")+COUNTIF(I14,"A")+COUNTIF(J14,"A")+COUNTIF(K14,"A")+COUNTIF(L14,"A")+COUNTIF(M14,"A")+COUNTIF(N14,"A")+COUNTIF(O14,"A")+COUNTIF(P14,"A")+COUNTIF(Q14,"A")+COUNTIF(R14,"A")+COUNTIF(S14,"A")+COUNTIF(T14,"A")+COUNTIF(U14,"A")+COUNTIF(V14,"A")+COUNTIF(W14,"A")+COUNTIF(X14,"A")+COUNTIF(Y14,"A")+COUNTIF(Z14,"A")+COUNTIF(AA14,"A")+COUNTIF(AB14,"A")+COUNTIF(AC14,"A")+COUNTIF(AD14,"A")+COUNTIF(AE14,"A")+COUNTIF(AF14,"A")+COUNTIF(AG14,"A")+COUNTIF(AH14,"A")+COUNTIF(AI14,"A")+COUNTIF(AJ14,"A")+COUNTIF(AK14,"A")+COUNTIF(AL14,"A") -> 22 | AN14: =COUNTIF(G14,"F")+COUNTIF(H14,"F")+COUNTIF(I14,"F")+COUNTIF(J14,"F")+COUNTIF(K14,"F")+COUNTIF(L14,"F")+COUNTIF(M14,"F")+COUNTIF(N14,"F")+COUNTIF(O14,"F")+COUNTIF(P14,"F")+COUNTIF(Q14,"F")+COUNTIF(R14,"F")+COUNTIF(S14,"F")+COUNTIF(T14,"F")+COUNTIF(U14,"F")+COUNTIF(V14,"F")+COUNTIF(W14,"F")+COUNTIF(X14,"F")+COUNTIF(Y14,"F")+COUNTIF(Z14,"F")+COUNTIF(AA14,"F")+COUNTIF(AB14,"F")+COUNTIF(AC14,"F")+COUNTIF(AD14,"F")+COUNTIF(AE14,"F")+COUNTIF(AF14,"F")+COUNTIF(AG14,"F")+COUNTIF(AH14,"F")+COUNTIF(AI14,"F")+COUNTIF(AJ14,"F")+COUNTIF(AK14,"F")+COUNTIF(AL14,"F") -> 0 | AO14: =IF(AM14=0,"",AM14/32) -> 0.6875
A15: 10 | B15: GERALDO RUBIO | C15: JUAN ANTONIO | D15: 224164554 | E15: 1 | F15: =IFERROR(ROUND(_xlfn.XLOOKUP(B15&" "&C15,'Examen 1'!B$2:B$27,'Examen 1'!E$2:E$27,0)/100*5,1),0) -> 5 | G15: A | H15: A | I15: A | J15: A | K15: A | L15: A | M15: A | N15: A | O15: A | P15: A | Q15: A | R15: A | S15: A | T15: A | U15: A | V15: A | W15: A | X15: - | Y15: - | Z15: - | AA15: A | AB15: A | AC15: A | AD15: A | AE15: A | AM15: =COUNTIF(G15,"A")+COUNTIF(H15,"A")+COUNTIF(I15,"A")+COUNTIF(J15,"A")+COUNTIF(K15,"A")+COUNTIF(L15,"A")+COUNTIF(M15,"A")+COUNTIF(N15,"A")+COUNTIF(O15,"A")+COUNTIF(P15,"A")+COUNTIF(Q15,"A")+COUNTIF(R15,"A")+COUNTIF(S15,"A")+COUNTIF(T15,"A")+COUNTIF(U15,"A")+COUNTIF(V15,"A")+COUNTIF(W15,"A")+COUNTIF(X15,"A")+COUNTIF(Y15,"A")+COUNTIF(Z15,"A")+COUNTIF(AA15,"A")+COUNTIF(AB15,"A")+COUNTIF(AC15,"A")+COUNTIF(AD15,"A")+COUNTIF(AE15,"A")+COUNTIF(AF15,"A")+COUNTIF(AG15,"A")+COUNTIF(AH15,"A")+COUNTIF(AI15,"A")+COUNTIF(AJ15,"A")+COUNTIF(AK15,"A")+COUNTIF(AL15,"A") -> 22 | AN15: =COUNTIF(G15,"F")+COUNTIF(H15,"F")+COUNTIF(I15,"F")+COUNTIF(J15,"F")+COUNTIF(K15,"F")+COUNTIF(L15,"F")+COUNTIF(M15,"F")+COUNTIF(N15,"F")+COUNTIF(O15,"F")+COUNTIF(P15,"F")+COUNTIF(Q15,"F")+COUNTIF(R15,"F")+COUNTIF(S15,"F")+COUNTIF(T15,"F")+COUNTIF(U15,"F")+COUNTIF(V15,"F")+COUNTIF(W15,"F")+COUNTIF(X15,"F")+COUNTIF(Y15,"F")+COUNTIF(Z15,"F")+COUNTIF(AA15,"F")+COUNTIF(AB15,"F")+COUNTIF(AC15,"F")+COUNTIF(AD15,"F")+COUNTIF(AE15,"F")+COUNTIF(AF15,"F")+COUNTIF(AG15,"F")+COUNTIF(AH15,"F")+COUNTIF(AI15,"F")+COUNTIF(AJ15,"F")+COUNTIF(AK15,"F")+COUNTIF(AL15,"F") -> 0 | AO15: =IF(AM15=0,"",AM15/32) -> 0.6875
A16: 11 | B16: GOMEZ CASTORENA | C16: ERICK JOSUE | D16: 212477198 | F16: =IFERROR(ROUND(_xlfn.XLOOKUP(B16&" "&C16,'Examen 1'!B$2:B$27,'Examen 1'!E$2:E$27,0)/100*5,1),0) -> 2.7 | G16: A | H16: A | I16: A | J16: A | K16: A | L16: A | M16: A | N16: A | O16: A | P16: A | Q16: A | R16: A | S16: A | T16: A | U16: A | V16: A | W16: A | X16: - | Y16: - | Z16: - | AA16: A | AB16: A | AC16: A | AD16: A | AE16: A | AM16: =COUNTIF(G16,"A")+COUNTIF(H16,"A")+COUNTIF(I16,"A")+COUNTIF(J16,"A")+COUNTIF(K16,"A")+COUNTIF(L16,"A")+COUNTIF(M16,"A")+COUNTIF(N16,"A")+COUNTIF(O16,"A")+COUNTIF(P16,"A")+COUNTIF(Q16,"A")+COUNTIF(R16,"A")+COUNTIF(S16,"A")+COUNTIF(T16,"A")+COUNTIF(U16,"A")+COUNTIF(V16,"A")+COUNTIF(W16,"A")+COUNTIF(X16,"A")+COUNTIF(Y16,"A")+COUNTIF(Z16,"A")+COUNTIF(AA16,"A")+COUNTIF(AB16,"A")+COUNTIF(AC16,"A")+COUNTIF(AD16,"A")+COUNTIF(AE16,"A")+COUNTIF(AF16,"A")+COUNTIF(AG16,"A")+COUNTIF(AH16,"A")+COUNTIF(AI16,"A")+COUNTIF(AJ16,"A")+COUNTIF(AK16,"A")+COUNTIF(AL16,"A") -> 22 | AN16: =COUNTIF(G16,"F")+COUNTIF(H16,"F")+COUNTIF(I16,"F")+COUNTIF(J16,"F")+COUNTIF(K16,"F")+COUNTIF(L16,"F")+COUNTIF(M16,"F")+COUNTIF(N16,"F")+COUNTIF(O16,"F")+COUNTIF(P16,"F")+COUNTIF(Q16,"F")+COUNTIF(R16,"F")+COUNTIF(S16,"F")+COUNTIF(T16,"F")+COUNTIF(U16,"F")+COUNTIF(V16,"F")+COUNTIF(W16,"F")+COUNTIF(X16,"F")+COUNTIF(Y16,"F")+COUNTIF(Z16,"F")+COUNTIF(AA16,"F")+COUNTIF(AB16,"F")+COUNTIF(AC16,"F")+COUNTIF(AD16,"F")+COUNTIF(AE16,"F")+COUNTIF(AF16,"F")+COUNTIF(AG16,"F")+COUNTIF(AH16,"F")+COUNTIF(AI16,"F")+COUNTIF(AJ16,"F")+COUNTIF(AK16,"F")+COUNTIF(AL16,"F") -> 0 | AO16: =IF(AM16=0,"",AM16/32) -> 0.6875
A17: 12 | B17: GONZALEZ CALVILLO | C17: TANIA MARIA | D17: 221597082 | F17: =IFERROR(ROUND(_xlfn.XLOOKUP(B17&" "&C17,'Examen 1'!B$2:B$27,'Examen 1'!E$2:E$27,0)/100*5,1),0) -> 5 | G17: A | H17: A | I17: A | J17: A | K17: A | L17: A | M17: A | N17: A | O17: A | P17: A | Q17: A | R17: A | S17: A | T17: A | U17: A | V17: A | W17: A | X17: - | Y17: - | Z17: - | AA17: A | AB17: A | AC17: A | AD17: A | AE17: A | AM17: =COUNTIF(G17,"A")+COUNTIF(H17,"A")+COUNTIF(I17,"A")+COUNTIF(J17,"A")+COUNTIF(K17,"A")+COUNTIF(L17,"A")+COUNTIF(M17,"A")+COUNTIF(N17,"A")+COUNTIF(O17,"A")+COUNTIF(P17,"A")+COUNTIF(Q17,"A")+COUNTIF(R17,"A")+COUNTIF(S17,"A")+COUNTIF(T17,"A")+COUNTIF(U17,"A")+COUNTIF(V17,"A")+COUNTIF(W17,"A")+COUNTIF(X17,"A")+COUNTIF(Y17,"A")+COUNTIF(Z17,"A")+COUNTIF(AA17,"A")+COUNTIF(AB17,"A")+COUNTIF(AC17,"A")+COUNTIF(AD17,"A")+COUNTIF(AE17,"A")+COUNTIF(AF17,"A")+COUNTIF(AG17,"A")+COUNTIF(AH17,"A")+COUNTIF(AI17,"A")+COUNTIF(AJ17,"A")+COUNTIF(AK17,"A")+COUNTIF(AL17,"A") -> 22 | AN17: =COUNTIF(G17,"F")+COUNTIF(H17,"F")+COUNTIF(I17,"F")+COUNTIF(J17,"F")+COUNTIF(K17,"F")+COUNTIF(L17,"F")+COUNTIF(M17,"F")+COUNTIF(N17,"F")+COUNTIF(O17,"F")+COUNTIF(P17,"F")+COUNTIF(Q17,"F")+COUNTIF(R17,"F")+COUNTIF(S17,"F")+COUNTIF(T17,"F")+COUNTIF(U17,"F")+COUNTIF(V17,"F")+COUNTIF(W17,"F")+COUNTIF(X17,"F")+COUNTIF(Y17,"F")+COUNTIF(Z17,"F")+COUNTIF(AA17,"F")+COUNTIF(AB17,"F")+COUNTIF(AC17,"F")+COUNTIF(AD17,"F")+COUNTIF(AE17,"F")+COUNTIF(AF17,"F")+COUNTIF(AG17,"F")+COUNTIF(AH17,"F")+COUNTIF(AI17,"F")+COUNTIF(AJ17,"F")+COUNTIF(AK17,"F")+COUNTIF(AL17,"F") -> 0 | AO17: =IF(AM17=0,"",AM17/32) -> 0.6875
A18: 13 | B18: GONZALEZ CUELLAR | C18: EDGAR OSWALDO | D18: 221217808 | F18: =IFERROR(ROUND(_xlfn.XLOOKUP(B18&" "&C18,'Examen 1'!B$2:B$27,'Examen 1'!E$2:E$27,0)/100*5,1),0) -> 4.7 | G18: A | H18: A | I18: A | J18: A | K18: A | L18: A | M18: A | N18: A | O18: A | P18: A | Q18: A | R18: A | S18: A | T18: A | U18: A | V18: A | W18: A | X18: - | Y18: - | Z18: - | AA18: A | AB18: A | AC18: A | AD18: A | AE18: A | AM18: =COUNTIF(G18,"A")+COUNTIF(H18,"A")+COUNTIF(I18,"A")+COUNTIF(J18,"A")+COUNTIF(K18,"A")+COUNTIF(L18,"A")+COUNTIF(M18,"A")+COUNTIF(N18,"A")+COUNTIF(O18,"A")+COUNTIF(P18,"A")+COUNTIF(Q18,"A")+COUNTIF(R18,"A")+COUNTIF(S18,"A")+COUNTIF(T18,"A")+COUNTIF(U18,"A")+COUNTIF(V18,"A")+COUNTIF(W18,"A")+COUNTIF(X18,"A")+COUNTIF(Y18,"A")+COUNTIF(Z18,"A")+COUNTIF(AA18,"A")+COUNTIF(AB18,"A")+COUNTIF(AC18,"A")+COUNTIF(AD18,"A")+COUNTIF(AE18,"A")+COUNTIF(AF18,"A")+COUNTIF(AG18,"A")+COUNTIF(AH18,"A")+COUNTIF(AI18,"A")+COUNTIF(AJ18,"A")+COUNTIF(AK18,"A")+COUNTIF(AL18,"A") -> 22 | AN18: =COUNTIF(G18,"F")+COUNTIF(H18,"F")+COUNTIF(I18,"F")+COUNTIF(J18,"F")+COUNTIF(K18,"F")+COUNTIF(L18,"F")+COUNTIF(M18,"F")+COUNTIF(N18,"F")+COUNTIF(O18,"F")+COUNTIF(P18,"F")+COUNTIF(Q18,"F")+COUNTIF(R18,"F")+COUNTIF(S18,"F")+COUNTIF(T18,"F")+COUNTIF(U18,"F")+COUNTIF(V18,"F")+COUNTIF(W18,"F")+COUNTIF(X18,"F")+COUNTIF(Y18,"F")+COUNTIF(Z18,"F")+COUNTIF(AA18,"F")+COUNTIF(AB18,"F")+COUNTIF(AC18,"F")+COUNTIF(AD18,"F")+COUNTIF(AE18,"F")+COUNTIF(AF18,"F")+COUNTIF(AG18,"F")+COUNTIF(AH18,"F")+COUNTIF(AI18,"F")+COUNTIF(AJ18,"F")+COUNTIF(AK18,"F")+COUNTIF(AL18,"F") -> 0 | AO18: =IF(AM18=0,"",AM18/32) -> 0.6875
A19: 14 | B19: GONZALEZ MEDRANO | C19: LILIANA ARALI | D19: 218510383 | E19: 1 | F19: =IFERROR(ROUND(_xlfn.XLOOKUP(B19&" "&C19,'Examen 1'!B$2:B$27,'Examen 1'!E$2:E$27,0)/100*5,1),0) -> 4.9 | G19: A | H19: A | I19: A | J19: A | K19: A | L19: A | M19: A | N19: A | O19: A | P19: A | Q19: A | R19: A | S19: A | T19: A | U19: A | V19: A | W19: A | X19: - | Y19: - | Z19: - | AA19: A | AB19: A | AC19: A | AD19: A | AE19: A | AM19: =COUNTIF(G19,"A")+COUNTIF(H19,"A")+COUNTIF(I19,"A")+COUNTIF(J19,"A")+COUNTIF(K19,"A")+COUNTIF(L19,"A")+COUNTIF(M19,"A")+COUNTIF(N19,"A")+COUNTIF(O19,"A")+COUNTIF(P19,"A")+COUNTIF(Q19,"A")+COUNTIF(R19,"A")+COUNTIF(S19,"A")+COUNTIF(T19,"A")+COUNTIF(U19,"A")+COUNTIF(V19,"A")+COUNTIF(W19,"A")+COUNTIF(X19,"A")+COUNTIF(Y19,"A")+COUNTIF(Z19,"A")+COUNTIF(AA19,"A")+COUNTIF(AB19,"A")+COUNTIF(AC19,"A")+COUNTIF(AD19,"A")+COUNTIF(AE19,"A")+COUNTIF(AF19,"A")+COUNTIF(AG19,"A")+COUNTIF(AH19,"A")+COUNTIF(AI19,"A")+COUNTIF(AJ19,"A")+COUNTIF(AK19,"A")+COUNTIF(AL19,"A") -> 22 | AN19: =COUNTIF(G19,"F")+COUNTIF(H19,"F")+COUNTIF(I19,"F")+COUNTIF(J19,"F")+COUNTIF(K19,"F")+COUNTIF(L19,"F")+COUNTIF(M19,"F")+COUNTIF(N19,"F")+COUNTIF(O19,"F")+COUNTIF(P19,"F")+COUNTIF(Q19,"F")+COUNTIF(R19,"F")+COUNTIF(S19,"F")+COUNTIF(T19,"F")+COUNTIF(U19,"F")+COUNTIF(V19,"F")+COUNTIF(W19,"F")+COUNTIF(X19,"F")+COUNTIF(Y19,"F")+COUNTIF(Z19,"F")+COUNTIF(AA19,"F")+COUNTIF(AB19,"F")+COUNTIF(AC19,"F")+COUNTIF(AD19,"F")+COUNTIF(AE19,"F")+COUNTIF(AF19,"F")+COUNTIF(AG19,"F")+COUNTIF(AH19,"F")+COUNTIF(AI19,"F")+COUNTIF(AJ19,"F")+COUNTIF(AK19,"F")+COUNTIF(AL19,"F") -> 0 | AO19: =IF(AM19=0,"",AM19/32) -> 0.6875
A20: 15 | B20: HERNANDEZ VENEGAS | C20: TABATA CRISTINA | D20: 219873528 | F20: =IFERROR(ROUND(_xlfn.XLOOKUP(B20&" "&C20,'Examen 1'!B$2:B$27,'Examen 1'!E$2:E$27,0)/100*5,1),0) -> 4.8 | G20: A | H20: A | I20: A | J20: A | K20: A | L20: A | M20: A | N20: A | O20: A | P20: A | Q20: A | R20: A | S20: A | T20: A | U20: A | V20: A | W20: A | X20: - | Y20: - | Z20: - | AA20: A | AB20: A | AC20: A | AD20: A | AE20: A | AM20: =COUNTIF(G20,"A")+COUNTIF(H20,"A")+COUNTIF(I20,"A")+COUNTIF(J20,"A")+COUNTIF(K20,"A")+COUNTIF(L20,"A")+COUNTIF(M20,"A")+COUNTIF(N20,"A")+COUNTIF(O20,"A")+COUNTIF(P20,"A")+COUNTIF(Q20,"A")+COUNTIF(R20,"A")+COUNTIF(S20,"A")+COUNTIF(T20,"A")+COUNTIF(U20,"A")+COUNTIF(V20,"A")+COUNTIF(W20,"A")+COUNTIF(X20,"A")+COUNTIF(Y20,"A")+COUNTIF(Z20,"A")+COUNTIF(AA20,"A")+COUNTIF(AB20,"A")+COUNTIF(AC20,"A")+COUNTIF(AD20,"A")+COUNTIF(AE20,"A")+COUNTIF(AF20,"A")+COUNTIF(AG20,"A")+COUNTIF(AH20,"A")+COUNTIF(AI20,"A")+COUNTIF(AJ20,"A")+COUNTIF(AK20,"A")+COUNTIF(AL20,"A") -> 22 | AN20: =COUNTIF(G20,"F")+COUNTIF(H20,"F")+COUNTIF(I20,"F")+COUNTIF(J20,"F")+COUNTIF(K20,"F")+COUNTIF(L20,"F")+COUNTIF(M20,"F")+COUNTIF(N20,"F")+COUNTIF(O20,"F")+COUNTIF(P20,"F")+COUNTIF(Q20,"F")+COUNTIF(R20,"F")+COUNTIF(S20,"F")+COUNTIF(T20,"F")+COUNTIF(U20,"F")+COUNTIF(V20,"F")+COUNTIF(W20,"F")+COUNTIF(X20,"F")+COUNTIF(Y20,"F")+COUNTIF(Z20,"F")+COUNTIF(AA20,"F")+COUNTIF(AB20,"F")+COUNTIF(AC20,"F")+COUNTIF(AD20,"F")+COUNTIF(AE20,"F")+COUNTIF(AF20,"F")+COUNTIF(AG20,"F")+COUNTIF(AH20,"F")+COUNTIF(AI20,"F")+COUNTIF(AJ20,"F")+COUNTIF(AK20,"F")+COUNTIF(AL20,"F") -> 0 | AO20: =IF(AM20=0,"",AM20/32) -> 0.6875
A21: 16 | B21: HERNANDEZ VILLANUEVA | C21: VICTOR DANIEL | D21: 224164539 | F21: =IFERROR(ROUND(_xlfn.XLOOKUP(B21&" "&C21,'Examen 1'!B$2:B$27,'Examen 1'!E$2:E$27,0)/100*5,1),0) -> 5 | G21: A | H21: A | I21: A | J21: A | K21: A | L21: A | M21: A | N21: A | O21: A | P21: A | Q21: A | R21: A | S21: A | T21: A | U21: A | V21: A | W21: A | X21: - | Y21: - | Z21: - | AA21: A | AB21: A | AC21: A | AD21: A | AE21: A | AM21: =COUNTIF(G21,"A")+COUNTIF(H21,"A")+COUNTIF(I21,"A")+COUNTIF(J21,"A")+COUNTIF(K21,"A")+COUNTIF(L21,"A")+COUNTIF(M21,"A")+COUNTIF(N21,"A")+COUNTIF(O21,"A")+COUNTIF(P21,"A")+COUNTIF(Q21,"A")+COUNTIF(R21,"A")+COUNTIF(S21,"A")+COUNTIF(T21,"A")+COUNTIF(U21,"A")+COUNTIF(V21,"A")+COUNTIF(W21,"A")+COUNTIF(X21,"A")+COUNTIF(Y21,"A")+COUNTIF(Z21,"A")+COUNTIF(AA21,"A")+COUNTIF(AB21,"A")+COUNTIF(AC21,"A")+COUNTIF(AD21,"A")+COUNTIF(AE21,"A")+COUNTIF(AF21,"A")+COUNTIF(AG21,"A")+COUNTIF(AH21,"A")+COUNTIF(AI21,"A")+COUNTIF(AJ21,"A")+COUNTIF(AK21,"A")+COUNTIF(AL21,"A") -> 22 | AN21: =COUNTIF(G21,"F")+COUNTIF(H21,"F")+COUNTIF(I21,"F")+COUNTIF(J21,"F")+COUNTIF(K21,"F")+COUNTIF(L21,"F")+COUNTIF(M21,"F")+COUNTIF(N21,"F")+COUNTIF(O21,"F")+COUNTIF(P21,"F")+COUNTIF(Q21,"F")+COUNTIF(R21,"F")+COUNTIF(S21,"F")+COUNTIF(T21,"F")+COUNTIF(U21,"F")+COUNTIF(V21,"F")+COUNTIF(W21,"F")+COUNTIF(X21,"F")+COUNTIF(Y21,"F")+COUNTIF(Z21,"F")+COUNTIF(AA21,"F")+COUNTIF(AB21,"F")+COUNTIF(AC21,"F")+COUNTIF(AD21,"F")+COUNTIF(AE21,"F")+COUNTIF(AF21,"F")+COUNTIF(AG21,"F")+COUNTIF(AH21,"F")+COUNTIF(AI21,"F")+COUNTIF(AJ21,"F")+COUNTIF(AK21,"F")+COUNTIF(AL21,"F") -> 0 | AO21: =IF(AM21=0,"",AM21/32) -> 0.6875
A22: 17 | B22: IBARRA GRACIA | C22: DIEGO DAVID | D22: 218506645 | F22: =IFERROR(ROUND(_xlfn.XLOOKUP(B22&" "&C22,'Examen 1'!B$2:B$27,'Examen 1'!E$2:E$27,0)/100*5,1),0) -> 4.8 | G22: A | H22: A | I22: A | J22: A | K22: A | L22: A | M22: A | N22: A | O22: A | P22: A | Q22: A | R22: A | S22: A | T22: A | U22: A | V22: A | W22: A | X22: - | Y22: - | Z22: - | AA22: A | AB22: A | AC22: A | AD22: A | AE22: A | AM22: =COUNTIF(G22,"A")+COUNTIF(H22,"A")+COUNTIF(I22,"A")+COUNTIF(J22,"A")+COUNTIF(K22,"A")+COUNTIF(L22,"A")+COUNTIF(M22,"A")+COUNTIF(N22,"A")+COUNTIF(O22,"A")+COUNTIF(P22,"A")+COUNTIF(Q22,"A")+COUNTIF(R22,"A")+COUNTIF(S22,"A")+COUNTIF(T22,"A")+COUNTIF(U22,"A")+COUNTIF(V22,"A")+COUNTIF(W22,"A")+COUNTIF(X22,"A")+COUNTIF(Y22,"A")+COUNTIF(Z22,"A")+COUNTIF(AA22,"A")+COUNTIF(AB22,"A")+COUNTIF(AC22,"A")+COUNTIF(AD22,"A")+COUNTIF(AE22,"A")+COUNTIF(AF22,"A")+COUNTIF(AG22,"A")+COUNTIF(AH22,"A")+COUNTIF(AI22,"A")+COUNTIF(AJ22,"A")+COUNTIF(AK22,"A")+COUNTIF(AL22,"A") -> 22 | AN22: =COUNTIF(G22,"F")+COUNTIF(H22,"F")+COUNTIF(I22,"F")+COUNTIF(J22,"F")+COUNTIF(K22,"F")+COUNTIF(L22,"F")+COUNTIF(M22,"F")+COUNTIF(N22,"F")+COUNTIF(O22,"F")+COUNTIF(P22,"F")+COUNTIF(Q22,"F")+COUNTIF(R22,"F")+COUNTIF(S22,"F")+COUNTIF(T22,"F")+COUNTIF(U22,"F")+COUNTIF(V22,"F")+COUNTIF(W22,"F")+COUNTIF(X22,"F")+COUNTIF(Y22,"F")+COUNTIF(Z22,"F")+COUNTIF(AA22,"F")+COUNTIF(AB22,"F")+COUNTIF(AC22,"F")+COUNTIF(AD22,"F")+COUNTIF(AE22,"F")+COUNTIF(AF22,"F")+COUNTIF(AG22,"F")+COUNTIF(AH22,"F")+COUNTIF(AI22,"F")+COUNTIF(AJ22,"F")+COUNTIF(AK22,"F")+COUNTIF(AL22,"F") -> 0 | AO22: =IF(AM22=0,"",AM22/32) -> 0.6875
A23: 18 | B23: LAZOS CRUZ | C23: ALLISON | D23: 221488607 | F23: =IFERROR(ROUND(_xlfn.XLOOKUP(B23&" "&C23,'Examen 1'!B$2:B$27,'Examen 1'!E$2:E$27,0)/100*5,1),0) -> 5 | G23: A | H23: A | I23: A | J23: A | K23: A | L23: A | M23: A | N23: A | O23: A | P23: A | Q23: A | R23: A | S23: A | T23: A | U23: A | V23: A | W23: A | X23: - | Y23: - | Z23: - | AA23: A | AB23: A | AC23: A | AD23: A | AE23: A | AM23: =COUNTIF(G23,"A")+COUNTIF(H23,"A")+COUNTIF(I23,"A")+COUNTIF(J23,"A")+COUNTIF(K23,"A")+COUNTIF(L23,"A")+COUNTIF(M23,"A")+COUNTIF(N23,"A")+COUNTIF(O23,"A")+COUNTIF(P23,"A")+COUNTIF(Q23,"A")+COUNTIF(R23,"A")+COUNTIF(S23,"A")+COUNTIF(T23,"A")+COUNTIF(U23,"A")+COUNTIF(V23,"A")+COUNTIF(W23,"A")+COUNTIF(X23,"A")+COUNTIF(Y23,"A")+COUNTIF(Z23,"A")+COUNTIF(AA23,"A")+COUNTIF(AB23,"A")+COUNTIF(AC23,"A")+COUNTIF(AD23,"A")+COUNTIF(AE23,"A")+COUNTIF(AF23,"A")+COUNTIF(AG23,"A")+COUNTIF(AH23,"A")+COUNTIF(AI23,"A")+COUNTIF(AJ23,"A")+COUNTIF(AK23,"A")+COUNTIF(AL23,"A") -> 22 | AN23: =COUNTIF(G23,"F")+COUNTIF(H23,"F")+COUNTIF(I23,"F")+COUNTIF(J23,"F")+COUNTIF(K23,"F")+COUNTIF(L23,"F")+COUNTIF(M23,"F")+COUNTIF(N23,"F")+COUNTIF(O23,"F")+COUNTIF(P23,"F")+COUNTIF(Q23,"F")+COUNTIF(R23,"F")+COUNTIF(S23,"F")+COUNTIF(T23,"F")+COUNTIF(U23,"F")+COUNTIF(V23,"F")+COUNTIF(W23,"F")+COUNTIF(X23,"F")+COUNTIF(Y23,"F")+COUNTIF(Z23,"F")+COUNTIF(AA23,"F")+COUNTIF(AB23,"F")+COUNTIF(AC23,"F")+COUNTIF(AD23,"F")+COUNTIF(AE23,"F")+COUNTIF(AF23,"F")+COUNTIF(AG23,"F")+COUNTIF(AH23,"F")+COUNTIF(AI23,"F")+COUNTIF(AJ23,"F")+COUNTIF(AK23,"F")+COUNTIF(AL23,"F") -> 0 | AO23: =IF(AM23=0,"",AM23/32) -> 0.6875
A24: 19 | B24: MARTINEZ DURAN | C24: MAHONRI MORIANC | D24: 220468319 | F24: =IFERROR(ROUND(_xlfn.XLOOKUP(B24&" "&C24,'Examen 1'!B$2:B$27,'Examen 1'!E$2:E$27,0)/100*5,1),0) -> 5 | G24: A | H24: A | I24: A | J24: A | K24: A | L24: A | M24: A | N24: A | O24: A | P24: A | Q24: A | R24: A | S24: A | T24: A | U24: A | V24: A | W24: A | X24: - | Y24: - | Z24: - | AA24: A | AB24: A | AC24: A | AD24: A | AE24: A | AM24: =COUNTIF(G24,"A")+COUNTIF(H24,"A")+COUNTIF(I24,"A")+COUNTIF(J24,"A")+COUNTIF(K24,"A")+COUNTIF(L24,"A")+COUNTIF(M24,"A")+COUNTIF(N24,"A")+COUNTIF(O24,"A")+COUNTIF(P24,"A")+COUNTIF(Q24,"A")+COUNTIF(R24,"A")+COUNTIF(S24,"A")+COUNTIF(T24,"A")+COUNTIF(U24,"A")+COUNTIF(V24,"A")+COUNTIF(W24,"A")+COUNTIF(X24,"A")+COUNTIF(Y24,"A")+COUNTIF(Z24,"A")+COUNTIF(AA24,"A")+COUNTIF(AB24,"A")+COUNTIF(AC24,"A")+COUNTIF(AD24,"A")+COUNTIF(AE24,"A")+COUNTIF(AF24,"A")+COUNTIF(AG24,"A")+COUNTIF(AH24,"A")+COUNTIF(AI24,"A")+COUNTIF(AJ24,"A")+COUNTIF(AK24,"A")+COUNTIF(AL24,"A") -> 22 | AN24: =COUNTIF(G24,"F")+COUNTIF(H24,"F")+COUNTIF(I24,"F")+COUNTIF(J24,"F")+COUNTIF(K24,"F")+COUNTIF(L24,"F")+COUNTIF(M24,"F")+COUNTIF(N24,"F")+COUNTIF(O24,"F")+COUNTIF(P24,"F")+COUNTIF(Q24,"F")+COUNTIF(R24,"F")+COUNTIF(S24,"F")+COUNTIF(T24,"F")+COUNTIF(U24,"F")+COUNTIF(V24,"F")+COUNTIF(W24,"F")+COUNTIF(X24,"F")+COUNTIF(Y24,"F")+COUNTIF(Z24,"F")+COUNTIF(AA24,"F")+COUNTIF(AB24,"F")+COUNTIF(AC24,"F")+COUNTIF(AD24,"F")+COUNTIF(AE24,"F")+COUNTIF(AF24,"F")+COUNTIF(AG24,"F")+COUNTIF(AH24,"F")+COUNTIF(AI24,"F")+COUNTIF(AJ24,"F")+COUNTIF(AK24,"F")+COUNTIF(AL24,"F") -> 0 | AO24: =IF(AM24=0,"",AM24/32) -> 0.6875
A25: 20 | B25: MARTINEZ GUTIERREZ | C25: DIEGO EUGENIO | D25: 224164553 | F25: =IFERROR(ROUND(_xlfn.XLOOKUP(B25&" "&C25,'Examen 1'!B$2:B$27,'Examen 1'!E$2:E$27,0)/100*5,1),0) -> 5 | G25: A | H25: A | I25: A | J25: A | K25: A | L25: A | M25: A | N25: A | O25: A | P25: A | Q25: A | R25: A | S25: A | T25: A | U25: A | V25: A | W25: A | X25: - | Y25: - | Z25: - | AA25: A | AB25: A | AC25: A | AD25: A | AE25: A | AM25: =COUNTIF(G25,"A")+COUNTIF(H25,"A")+COUNTIF(I25,"A")+COUNTIF(J25,"A")+COUNTIF(K25,"A")+COUNTIF(L25,"A")+COUNTIF(M25,"A")+COUNTIF(N25,"A")+COUNTIF(O25,"A")+COUNTIF(P25,"A")+COUNTIF(Q25,"A")+COUNTIF(R25,"A")+COUNTIF(S25,"A")+COUNTIF(T25,"A")+COUNTIF(U25,"A")+COUNTIF(V25,"A")+COUNTIF(W25,"A")+COUNTIF(X25,"A")+COUNTIF(Y25,"A")+COUNTIF(Z25,"A")+COUNTIF(AA25,"A")+COUNTIF(AB25,"A")+COUNTIF(AC25,"A")+COUNTIF(AD25,"A")+COUNTIF(AE25,"A")+COUNTIF(AF25,"A")+COUNTIF(AG25,"A")+COUNTIF(AH25,"A")+COUNTIF(AI25,"A")+COUNTIF(AJ25,"A")+COUNTIF(AK25,"A")+COUNTIF(AL25,"A") -> 22 | AN25: =COUNTIF(G25,"F")+COUNTIF(H25,"F")+COUNTIF(I25,"F")+COUNTIF(J25,"F")+COUNTIF(K25,"F")+COUNTIF(L25,"F")+COUNTIF(M25,"F")+COUNTIF(N25,"F")+COUNTIF(O25,"F")+COUNTIF(P25,"F")+COUNTIF(Q25,"F")+COUNTIF(R25,"F")+COUNTIF(S25,"F")+COUNTIF(T25,"F")+COUNTIF(U25,"F")+COUNTIF(V25,"F")+COUNTIF(W25,"F")+COUNTIF(X25,"F")+COUNTIF(Y25,"F")+COUNTIF(Z25,"F")+COUNTIF(AA25,"F")+COUNTIF(AB25,"F")+COUNTIF(AC25,"F")+COUNTIF(AD25,"F")+COUNTIF(AE25,"F")+COUNTIF(AF25,"F")+COUNTIF(AG25,"F")+COUNTIF(AH25,"F")+COUNTIF(AI25,"F")+COUNTIF(AJ25,"F")+COUNTIF(AK25,"F")+COUNTIF(AL25,"F") -> 0 | AO25: =IF(AM25=0,"",AM25/32) -> 0.6875
A26: 21 | B26: MUÑOZ RIVAS | C26: JOSHUA | D26: 224164546 | F26: =IFERROR(ROUND(_xlfn.XLOOKUP(B26&" "&C26,'Examen 1'!B$2:B$27,'Examen 1'!E$2:E$27,0)/100*5,1),0) -> 5 | G26: A | H26: A | I26: A | J26: A | K26: A | L26: A | M26: A | N26: A | O26: A | P26: A | Q26: A | R26: A | S26: A | T26: A | U26: A | V26: A | W26: A | X26: - | Y26: - | Z26: - | AA26: A | AB26: A | AC26: A | AD26: A | AE26: A | AM26: =COUNTIF(G26,"A")+COUNTIF(H26,"A")+COUNTIF(I26,"A")+COUNTIF(J26,"A")+COUNTIF(K26,"A")+COUNTIF(L26,"A")+COUNTIF(M26,"A")+COUNTIF(N26,"A")+COUNTIF(O26,"A")+COUNTIF(P26,"A")+COUNTIF(Q26,"A")+COUNTIF(R26,"A")+COUNTIF(S26,"A")+COUNTIF(T26,"A")+COUNTIF(U26,"A")+COUNTIF(V26,"A")+COUNTIF(W26,"A")+COUNTIF(X26,"A")+COUNTIF(Y26,"A")+COUNTIF(Z26,"A")+COUNTIF(AA26,"A")+COUNTIF(AB26,"A")+COUNTIF(AC26,"A")+COUNTIF(AD26,"A")+COUNTIF(AE26,"A")+COUNTIF(AF26,"A")+COUNTIF(AG26,"A")+COUNTIF(AH26,"A")+COUNTIF(AI26,"A")+COUNTIF(AJ26,"A")+COUNTIF(AK26,"A")+COUNTIF(AL26,"A") -> 22 | AN26: =COUNTIF(G26,"F")+COUNTIF(H26,"F")+COUNTIF(I26,"F")+COUNTIF(J26,"F")+COUNTIF(K26,"F")+COUNTIF(L26,"F")+COUNTIF(M26,"F")+COUNTIF(N26,"F")+COUNTIF(O26,"F")+COUNTIF(P26,"F")+COUNTIF(Q26,"F")+COUNTIF(R26,"F")+COUNTIF(S26,"F")+COUNTIF(T26,"F")+COUNTIF(U26,"F")+COUNTIF(V26,"F")+COUNTIF(W26,"F")+COUNTIF(X26,"F")+COUNTIF(Y26,"F")+COUNTIF(Z26,"F")+COUNTIF(AA26,"F")+COUNTIF(AB26,"F")+COUNTIF(AC26,"F")+COUNTIF(AD26,"F")+COUNTIF(AE26,"F")+COUNTIF(AF26,"F")+COUNTIF(AG26,"F")+COUNTIF(AH26,"F")+COUNTIF(AI26,"F")+COUNTIF(AJ26,"F")+COUNTIF(AK26,"F")+COUNTIF(AL26,"F") -> 0 | AO26: =IF(AM26=0,"",AM26/32) -> 0.6875
A27: 22 | B27: PEREZ GOMEZ | C27: MARIA ANDREA | D27: 216797103 | E27: 2 | F27: =IFERROR(ROUND(_xlfn.XLOOKUP(B27&" "&C27,'Examen 1'!B$2:B$27,'Examen 1'!E$2:E$27,0)/100*5,1),0) -> 3.1 | G27: A | H27: A | I27: A | J27: A | K27: A | L27: A | M27: A | N27: A | O27: A | P27: A | Q27: A | R27: A | S27: A | T27: A | U27: A | V27: A | W27: A | X27: - | Y27: - | Z27: - | AA27: A | AB27: A | AC27: A | AD27: A | AE27: A | AM27: =COUNTIF(G27,"A")+COUNTIF(H27,"A")+COUNTIF(I27,"A")+COUNTIF(J27,"A")+COUNTIF(K27,"A")+COUNTIF(L27,"A")+COUNTIF(M27,"A")+COUNTIF(N27,"A")+COUNTIF(O27,"A")+COUNTIF(P27,"A")+COUNTIF(Q27,"A")+COUNTIF(R27,"A")+COUNTIF(S27,"A")+COUNTIF(T27,"A")+COUNTIF(U27,"A")+COUNTIF(V27,"A")+COUNTIF(W27,"A")+COUNTIF(X27,"A")+COUNTIF(Y27,"A")+COUNTIF(Z27,"A")+COUNTIF(AA27,"A")+COUNTIF(AB27,"A")+COUNTIF(AC27,"A")+COUNTIF(AD27,"A")+COUNTIF(AE27,"A")+COUNTIF(AF27,"A")+COUNTIF(AG27,"A")+COUNTIF(AH27,"A")+COUNTIF(AI27,"A")+COUNTIF(AJ27,"A")+COUNTIF(AK27,"A")+COUNTIF(AL27,"A") -> 22 | AN27: =COUNTIF(G27,"F")+COUNTIF(H27,"F")+COUNTIF(I27,"F")+COUNTIF(J27,"F")+COUNTIF(K27,"F")+COUNTIF(L27,"F")+COUNTIF(M27,"F")+COUNTIF(N27,"F")+COUNTIF(O27,"F")+COUNTIF(P27,"F")+COUNTIF(Q27,"F")+COUNTIF(R27,"F")+COUNTIF(S27,"F")+COUNTIF(T27,"F")+COUNTIF(U27,"F")+COUNTIF(V27,"F")+COUNTIF(W27,"F")+COUNTIF(X27,"F")+COUNTIF(Y27,"F")+COUNTIF(Z27,"F")+COUNTIF(AA27,"F")+COUNTIF(AB27,"F")+COUNTIF(AC27,"F")+COUNTIF(AD27,"F")+COUNTIF(AE27,"F")+COUNTIF(AF27,"F")+COUNTIF(AG27,"F")+COUNTIF(AH27,"F")+COUNTIF(AI27,"F")+COUNTIF(AJ27,"F")+COUNTIF(AK27,"F")+COUNTIF(AL27,"F") -> 0 | AO27: =IF(AM27=0,"",AM27/32) -> 0.6875
A28: 23 | B28: PIMENTEL MELGOZA | C28: ISRAEL RICARDO | D28: 224164542 | F28: =IFERROR(ROUND(_xlfn.XLOOKUP(B28&" "&C28,'Examen 1'!B$2:B$27,'Examen 1'!E$2:E$27,0)/100*5,1),0) -> 5 | G28: A | H28: A | I28: A | J28: A | K28: A | L28: A | M28: A | N28: A | O28: A | P28: A | Q28: A | R28: A | S28: A | T28: A | U28: A | V28: A | W28: A | X28: - | Y28: - | Z28: - | AA28: A | AB28: A | AC28: A | AD28: A | AE28: A | AM28: =COUNTIF(G28,"A")+COUNTIF(H28,"A")+COUNTIF(I28,"A")+COUNTIF(J28,"A")+COUNTIF(K28,"A")+COUNTIF(L28,"A")+COUNTIF(M28,"A")+COUNTIF(N28,"A")+COUNTIF(O28,"A")+COUNTIF(P28,"A")+COUNTIF(Q28,"A")+COUNTIF(R28,"A")+COUNTIF(S28,"A")+COUNTIF(T28,"A")+COUNTIF(U28,"A")+COUNTIF(V28,"A")+COUNTIF(W28,"A")+COUNTIF(X28,"A")+COUNTIF(Y28,"A")+COUNTIF(Z28,"A")+COUNTIF(AA28,"A")+COUNTIF(AB28,"A")+COUNTIF(AC28,"A")+COUNTIF(AD28,"A")+COUNTIF(AE28,"A")+COUNTIF(AF28,"A")+COUNTIF(AG28,"A")+COUNTIF(AH28,"A")+COUNTIF(AI28,"A")+COUNTIF(AJ28,"A")+COUNTIF(AK28,"A")+COUNTIF(AL28,"A") -> 22 | AN28: =COUNTIF(G28,"F")+COUNTIF(H28,"F")+COUNTIF(I28,"F")+COUNTIF(J28,"F")+COUNTIF(K28,"F")+COUNTIF(L28,"F")+COUNTIF(M28,"F")+COUNTIF(N28,"F")+COUNTIF(O28,"F")+COUNTIF(P28,"F")+COUNTIF(Q28,"F")+COUNTIF(R28,"F")+COUNTIF(S28,"F")+COUNTIF(T28,"F")+COUNTIF(U28,"F")+COUNTIF(V28,"F")+COUNTIF(W28,"F")+COUNTIF(X28,"F")+COUNTIF(Y28,"F")+COUNTIF(Z28,"F")+COUNTIF(AA28,"F")+COUNTIF(AB28,"F")+COUNTIF(AC28,"F")+COUNTIF(AD28,"F")+COUNTIF(AE28,"F")+COUNTIF(AF28,"F")+COUNTIF(AG28,"F")+COUNTIF(AH28,"F")+COUNTIF(AI28,"F")+COUNTIF(AJ28,"F")+COUNTIF(AK28,"F")+COUNTIF(AL28,"F") -> 0 | AO28: =IF(AM28=0,"",AM28/32) -> 0.6875
A29: 24 | B29: PONCE RAMIREZ | C29: JORGE ALBERTO | D29: 210610982 | E29: 1.5 | F29: =IFERROR(ROUND(_xlfn.XLOOKUP(B29&" "&C29,'Examen 1'!B$2:B$27,'Examen 1'!E$2:E$27,0)/100*5,1),0) -> 3.2 | G29: A | H29: A | I29: A | J29: A | K29: A | L29: A | M29: A | N29: A | O29: A | P29: A | Q29: A | R29: A | S29: A | T29: A | U29: A | V29: A | W29: A | X29: - | Y29: - | Z29: - | AA29: A | AB29: A | AC29: A | AD29: A | AE29: A | AM29: =COUNTIF(G29,"A")+COUNTIF(H29,"A")+COUNTIF(I29,"A")+COUNTIF(J29,"A")+COUNTIF(K29,"A")+COUNTIF(L29,"A")+COUNTIF(M29,"A")+COUNTIF(N29,"A")+COUNTIF(O29,"A")+COUNTIF(P29,"A")+COUNTIF(Q29,"A")+COUNTIF(R29,"A")+COUNTIF(S29,"A")+COUNTIF(T29,"A")+COUNTIF(U29,"A")+COUNTIF(V29,"A")+COUNTIF(W29,"A")+COUNTIF(X29,"A")+COUNTIF(Y29,"A")+COUNTIF(Z29,"A")+COUNTIF(AA29,"A")+COUNTIF(AB29,"A")+COUNTIF(AC29,"A")+COUNTIF(AD29,"A")+COUNTIF(AE29,"A")+COUNTIF(AF29,"A")+COUNTIF(AG29,"A")+COUNTIF(AH29,"A")+COUNTIF(AI29,"A")+COUNTIF(AJ29,"A")+COUNTIF(AK29,"A")+COUNTIF(AL29,"A") -> 22 | AN29: =COUNTIF(G29,"F")+COUNTIF(H29,"F")+COUNTIF(I29,"F")+COUNTIF(J29,"F")+COUNTIF(K29,"F")+COUNTIF(L29,"F")+COUNTIF(M29,"F")+COUNTIF(N29,"F")+COUNTIF(O29,"F")+COUNTIF(P29,"F")+COUNTIF(Q29,"F")+COUNTIF(R29,"F")+COUNTIF(S29,"F")+COUNTIF(T29,"F")+COUNTIF(U29,"F")+COUNTIF(V29,"F")+COUNTIF(W29,"F")+COUNTIF(X29,"F")+COUNTIF(Y29,"F")+COUNTIF(Z29,"F")+COUNTIF(AA29,"F")+COUNTIF(AB29,"F")+COUNTIF(AC29,"F")+COUNTIF(AD29,"F")+COUNTIF(AE29,"F")+COUNTIF(AF29,"F")+COUNTIF(AG29,"F")+COUNTIF(AH29,"F")+COUNTIF(AI29,"F")+COUNTIF(AJ29,"F")+COUNTIF(AK29,"F")+COUNTIF(AL29,"F") -> 0 | AO29: =IF(AM29=0,"",AM29/32) -> 0.6875
A30: 25 | B30: REYES OLMEDO | C30: CHRISTIAN ALEJA | D30: 302356759 | E30: 1 | F30: =IFERROR(ROUND(_xlfn.XLOOKUP(B30&" "&C30,'Examen 1'!B$2:B$27,'Examen 1'!E$2:E$27,0)/100*5,1),0) -> 4.5 | G30: A | H30: A | I30: A | J30: A | K30: A | L30: A | M30: A | N30: A | O30: A | P30: A | Q30: A | R30: A | S30: A | T30: A | U30: A | V30: A | W30: A | X30: - | Y30: - | Z30: - | AA30: A | AB30: A | AC30: A | AD30: A | AE30: A | AM30: =COUNTIF(G30,"A")+COUNTIF(H30,"A")+COUNTIF(I30,"A")+COUNTIF(J30,"A")+COUNTIF(K30,"A")+COUNTIF(L30,"A")+COUNTIF(M30,"A")+COUNTIF(N30,"A")+COUNTIF(O30,"A")+COUNTIF(P30,"A")+COUNTIF(Q30,"A")+COUNTIF(R30,"A")+COUNTIF(S30,"A")+COUNTIF(T30,"A")+COUNTIF(U30,"A")+COUNTIF(V30,"A")+COUNTIF(W30,"A")+COUNTIF(X30,"A")+COUNTIF(Y30,"A")+COUNTIF(Z30,"A")+COUNTIF(AA30,"A")+COUNTIF(AB30,"A")+COUNTIF(AC30,"A")+COUNTIF(AD30,"A")+COUNTIF(AE30,"A")+COUNTIF(AF30,"A")+COUNTIF(AG30,"A")+COUNTIF(AH30,"A")+COUNTIF(AI30,"A")+COUNTIF(AJ30,"A")+COUNTIF(AK30,"A")+COUNTIF(AL30,"A") -> 22 | AN30: =COUNTIF(G30,"F")+COUNTIF(H30,"F")+COUNTIF(I30,"F")+COUNTIF(J30,"F")+COUNTIF(K30,"F")+COUNTIF(L30,"F")+COUNTIF(M30,"F")+COUNTIF(N30,"F")+COUNTIF(O30,"F")+COUNTIF(P30,"F")+COUNTIF(Q30,"F")+COUNTIF(R30,"F")+COUNTIF(S30,"F")+COUNTIF(T30,"F")+COUNTIF(U30,"F")+COUNTIF(V30,"F")+COUNTIF(W30,"F")+COUNTIF(X30,"F")+COUNTIF(Y30,"F")+COUNTIF(Z30,"F")+COUNTIF(AA30,"F")+COUNTIF(AB30,"F")+COUNTIF(AC30,"F")+COUNTIF(AD30,"F")+COUNTIF(AE30,"F")+COUNTIF(AF30,"F")+COUNTIF(AG30,"F")+COUNTIF(AH30,"F")+COUNTIF(AI30,"F")+COUNTIF(AJ30,"F")+COUNTIF(AK30,"F")+COUNTIF(AL30,"F") -> 0 | AO30: =IF(AM30=0,"",AM30/32) -> 0.6875
A31: 26 | B31: ROJAS BOBADILLA | C31: ALVARO ARTURO | D31: 224164555 | E31: 2 | F31: =IFERROR(ROUND(_xlfn.XLOOKUP(B31&" "&C31,'Examen 1'!B$2:B$27,'Examen 1'!E$2:E$27,0)/100*5,1),0) -> 3.9 | G31: A | H31: A | I31: A | J31: A | K31: A | L31: A | M31: A | N31: A | O31: A | P31: A | Q31: A | R31: A | S31: A | T31: A | U31: A | V31: A | W31: A | X31: - | Y31: - | Z31: - | AA31: A | AB31: A | AC31: A | AD31: A | AE31: A | AM31: =COUNTIF(G31,"A")+COUNTIF(H31,"A")+COUNTIF(I31,"A")+COUNTIF(J31,"A")+COUNTIF(K31,"A")+COUNTIF(L31,"A")+COUNTIF(M31,"A")+COUNTIF(N31,"A")+COUNTIF(O31,"A")+COUNTIF(P31,"A")+COUNTIF(Q31,"A")+COUNTIF(R31,"A")+COUNTIF(S31,"A")+COUNTIF(T31,"A")+COUNTIF(U31,"A")+COUNTIF(V31,"A")+COUNTIF(W31,"A")+COUNTIF(X31,"A")+COUNTIF(Y31,"A")+COUNTIF(Z31,"A")+COUNTIF(AA31,"A")+COUNTIF(AB31,"A")+COUNTIF(AC31,"A")+COUNTIF(AD31,"A")+COUNTIF(AE31,"A")+COUNTIF(AF31,"A")+COUNTIF(AG31,"A")+COUNTIF(AH31,"A")+COUNTIF(AI31,"A")+COUNTIF(AJ31,"A")+COUNTIF(AK31,"A")+COUNTIF(AL31,"A") -> 22 | AN31: =COUNTIF(G31,"F")+COUNTIF(H31,"F")+COUNTIF(I31,"F")+COUNTIF(J31,"F")+COUNTIF(K31,"F")+COUNTIF(L31,"F")+COUNTIF(M31,"F")+COUNTIF(N31,"F")+COUNTIF(O31,"F")+COUNTIF(P31,"F")+COUNTIF(Q31,"F")+COUNTIF(R31,"F")+COUNTIF(S31,"F")+COUNTIF(T31,"F")+COUNTIF(U31,"F")+COUNTIF(V31,"F")+COUNTIF(W31,"F")+COUNTIF(X31,"F")+COUNTIF(Y31,"F")+COUNTIF(Z31,"F")+COUNTIF(AA31,"F")+COUNTIF(AB31,"F")+COUNTIF(AC31,"F")+COUNTIF(AD31,"F")+COUNTIF(AE31,"F")+COUNTIF(AF31,"F")+COUNTIF(AG31,"F")+COUNTIF(AH31,"F")+COUNTIF(AI31,"F")+COUNTIF(AJ31,"F")+COUNTIF(AK31,"F")+COUNTIF(AL31,"F") -> 0 | AO31: =IF(AM31=0,"",AM31/32) -> 0.6875
A32: 27 | B32: ZARAGOZA BRAMBILA | C32: FABIAN ISAI | D32: 220417773 | E32: 1 | F32: =IFERROR(ROUND(_xlfn.XLOOKUP(B32&" "&C32,'Examen 1'!B$2:B$27,'Examen 1'!E$2:E$27,0)/100*5,1),0) -> 5 | G32: A | H32: A | I32: A | J32: A | K32: A | L32: A | M32: A | N32: A | O32: A | P32: A | Q32: A | R32: A | S32: A | T32: A | U32: A | V32: A | W32: A | X32: - | Y32: - | Z32: - | AA32: A | AB32: A | AC32: A | AD32: A | AE32: A | AM32: =COUNTIF(G32,"A")+COUNTIF(H32,"A")+COUNTIF(I32,"A")+COUNTIF(J32,"A")+COUNTIF(K32,"A")+COUNTIF(L32,"A")+COUNTIF(M32,"A")+COUNTIF(N32,"A")+COUNTIF(O32,"A")+COUNTIF(P32,"A")+COUNTIF(Q32,"A")+COUNTIF(R32,"A")+COUNTIF(S32,"A")+COUNTIF(T32,"A")+COUNTIF(U32,"A")+COUNTIF(V32,"A")+COUNTIF(W32,"A")+COUNTIF(X32,"A")+COUNTIF(Y32,"A")+COUNTIF(Z32,"A")+COUNTIF(AA32,"A")+COUNTIF(AB32,"A")+COUNTIF(AC32,"A")+COUNTIF(AD32,"A")+COUNTIF(AE32,"A")+COUNTIF(AF32,"A")+COUNTIF(AG32,"A")+COUNTIF(AH32,"A")+COUNTIF(AI32,"A")+COUNTIF(AJ32,"A")+COUNTIF(AK32,"A")+COUNTIF(AL32,"A") -> 22 | AN32: =COUNTIF(G32,"F")+COUNTIF(H32,"F")+COUNTIF(I32,"F")+COUNTIF(J32,"F")+COUNTIF(K32,"F")+COUNTIF(L32,"F")+COUNTIF(M32,"F")+COUNTIF(N32,"F")+COUNTIF(O32,"F")+COUNTIF(P32,"F")+COUNTIF(Q32,"F")+COUNTIF(R32,"F")+COUNTIF(S32,"F")+COUNTIF(T32,"F")+COUNTIF(U32,"F")+COUNTIF(V32,"F")+COUNTIF(W32,"F")+COUNTIF(X32,"F")+COUNTIF(Y32,"F")+COUNTIF(Z32,"F")+COUNTIF(AA32,"F")+COUNTIF(AB32,"F")+COUNTIF(AC32,"F")+COUNTIF(AD32,"F")+COUNTIF(AE32,"F")+COUNTIF(AF32,"F")+COUNTIF(AG32,"F")+COUNTIF(AH32,"F")+COUNTIF(AI32,"F")+COUNTIF(AJ32,"F")+COUNTIF(AK32,"F")+COUNTIF(AL32,"F") -> 0 | AO32: =IF(AM32=0,"",AM32/32) -> 0.6875
A33: ASISTENCIAS POR SESIÓN | G33: =COUNTIF(G6:G32,"A") -> 27 | H33: =COUNTIF(H6:H32,"A") -> 27 | I33: =COUNTIF(I6:I32,"A") -> 27 | J33: =COUNTIF(J6:J32,"A") -> 27 | K33: =COUNTIF(K6:K32,"A") -> 27 | L33: =COUNTIF(L6:L32,"A") -> 27 | M33: =COUNTIF(M6:M32,"A") -> 27 | N33: =COUNTIF(N6:N32,"A") -> 27 | ... AL33: =COUNTIF(AL6:AL32,"A") -> 0
A34: ✅ "A" = Asistencia ❌ "F" = Falta 📝 "J" = Justificada (no cuenta en fórmula) ⬛ "—" = Sesión de vacaciones (bloqueada) Semana Santa: 30 Mar – 12 Abr 2026
AG35: Examen 2

Sheet Resumen
A1: RESUMEN DE ASISTENCIA — ARQ. SISTEMAS DE SEGURIDAD | Ciclo 2026-A | CRN 236396
A2: # | B2: APELLIDO(S) | C2: NOMBRE(S) | D2: CÓDIGO | E2: ASISTENCIAS | F2: FALTAS | G2: % ASIST. | H2: STATUS
A3: 1 | B3: ACOSTA SANDOVAL | C3: ROGELIO ESAU | D3: 220840099 | E3: =Asistencia!AM6 -> 22 | F3: =Asistencia!AN6 -> 0 | G3: =Asistencia!AO6 -> 0.6875 | H3: =IF(Asistencia!AO6="","Sin datos",IF(Asistencia!AO6>=0.8,"✅ Asistencia!AB6ARegular","⚠️ En riesgo")) -> ⚠️ En riesgo
A4: 2 | B4: ARIAS CASTELLON | C4: GABRIELA ESPERA | D4: 088404858 | E4: =Asistencia!AM7 -> 22 | F4: =Asistencia!AN7 -> 0 | G4: =Asistencia!AO7 -> 0.6875 | H4: =IF(Asistencia!AO7="","Sin datos",IF(Asistencia!AO7>=0.8,"✅ Regular","⚠️ En riesgo")) -> ⚠️ En riesgo
A5: 3 | B5: AVALOS RODRIGUEZ | C5: KAROL GUADALUPE | D5: 224164552 | E5: =Asistencia!AM8 -> 22 | F5: =Asistencia!AN8 -> 0 | G5: =Asistencia!AO8 -> 0.6875 | H5: =IF(Asistencia!AO8="","Sin datos",IF(Asistencia!AO8>=0.8,"✅ Regular","⚠️ En riesgo")) -> ⚠️ En riesgo
A6: 4 | B6: CARCAÑO AGUAYO | C6: ANDREA LISSETH | D6: 221449008 | E6: =Asistencia!AM9 -> 22 | F6: =Asistencia!AN9 -> 0 | G6: =Asistencia!AO9 -> 0.6875 | H6: =IF(Asistencia!AO9="","Sin datos",IF(Asistencia!AO9>=0.8,"✅ Regular","⚠️ En riesgo")) -> ⚠️ En riesgo
A7: 5 | B7: DE LA VEGA SANCHEZ | C7: ISIS KAROL | D7: 221450537 | E7: =Asistencia!AM10 -> 22 | F7: =Asistencia!AN10 -> 0 | G7: =Asistencia!AO10 -> 0.6875 | H7: =IF(Asistencia!AO10="","Sin datos",IF(Asistencia!AO10>=0.8,"✅ Regular","⚠️ En riesgo")) -> ⚠️ En riesgo
A8: 6 | B8: DE LUNA MOZQUEDA | C8: EMMANUEL | D8: 209015442 | E8: =Asistencia!AM11 -> 22 | F8: =Asistencia!AN11 -> 0 | G8: =Asistencia!AO11 -> 0.6875 | H8: =IF(Asistencia!AO11="","Sin datos",IF(Asistencia!AO11>=0.8,"✅ Regular","⚠️ En riesgo")) -> ⚠️ En riesgo
A9: 7 | B9: FRANCO ARELLANO | C9: DAPHNE WENDOLYN | D9: 219051455 | E9: =Asistencia!AM12 -> 22 | F9: =Asistencia!AN12 -> 0 | G9: =Asistencia!AO12 -> 0.6875 | H9: =IF(Asistencia!AO12="","Sin datos",IF(Asistencia!AO12>=0.8,"✅ Regular","⚠️ En riesgo")) -> ⚠️ En riesgo
A10: 8 | B10: FREGOSO SANCHEZ | C10: PAOLA | D10: 216592013 | E10: =Asistencia!AM13 -> 22 | F10: =Asistencia!AN13 -> 0 | G10: =Asistencia!AO13 -> 0.6875 | H10: =IF(Asistencia!AO13="","Sin datos",IF(Asistencia!AO13>=0.8,"✅ Regular","⚠️ En riesgo")) -> ⚠️ En riesgo
A11: 9 | B11: GARAY GUZMAN | C11: CRISTIAN RENE | D11: 220105445 | E11: =Asistencia!AM14 -> 22 | F11: =Asistencia!AN14 -> 0 | G11: =Asistencia!AO14 -> 0.6875 | H11: =IF(Asistencia!AO14="","Sin datos",IF(Asistencia!AO14>=0.8,"✅ Regular","⚠️ En riesgo")) -> ⚠️ En riesgo
A12: 10 | B12: GERALDO RUBIO | C12: JUAN ANTONIO | D12: 224164554 | E12: =Asistencia!AM15 -> 22 | F12: =Asistencia!AN15 -> 0 | G12: =Asistencia!AO15 -> 0.6875 | H12: =IF(Asistencia!AO15="","Sin datos",IF(Asistencia!AO15>=0.8,"✅ Regular","⚠️ En riesgo")) -> ⚠️ En riesgo
A13: 11 | B13: GOMEZ CASTORENA | C13: ERICK JOSUE | D13: 212477198 | E13: =Asistencia!AM16 -> 22 | F13: =Asistencia!AN16 -> 0 | G13: =Asistencia!AO16 -> 0.6875 | H13: =IF(Asistencia!AO16="","Sin datos",IF(Asistencia!AO16>=0.8,"✅ Regular","⚠️ En riesgo")) -> ⚠️ En riesgo
A14: 12 | B14: GONZALEZ CALVILLO | C14: TANIA MARIA | D14: 221597082 | E14: =Asistencia!AM17 -> 22 | F14: =Asistencia!AN17 -> 0 | G14: =Asistencia!AO17 -> 0.6875 | H14: =IF(Asistencia!AO17="","Sin datos",IF(Asistencia!AO17>=0.8,"✅ Regular","⚠️ En riesgo")) -> ⚠️ En riesgo
A15: 13 | B15: GONZALEZ CUELLAR | C15: EDGAR OSWALDO | D15: 221217808 | E15: =Asistencia!AM18 -> 22 | F15: =Asistencia!AN18 -> 0 | G15: =Asistencia!AO18 -> 0.6875 | H15: =IF(Asistencia!AO18="","Sin datos",IF(Asistencia!AO18>=0.8,"✅ Regular","⚠️ En riesgo")) -> ⚠️ En riesgo
... A29: 27 | B29: ZARAGOZA BRAMBILA | C29: FABIAN ISAI | D29: 220417773 | E29: =Asistencia!AM32 -> 22 | F29: =Asistencia!AN32 -> 0 | G29: =Asistencia!AO32 -> 0.6875 | H29: =IF(Asistencia!AO32="","Sin datos",IF(Asistencia!AO32>=0.8,"✅ Regular","⚠️ En riesgo")) -> ⚠️ En riesgo

Sheet Examen 1
A1: Marca temporal | B1: Nombre de Alumno | C1: Dirección de correo electrónico | D1: Puntuación Provisional | E1: Puntuación | F1: 1. Una empresa descubre que un atacante accedió a su base de datos de clientes y copió 2 millones de registros sin modificar nada. ¿Qué pilar del CIA Triad fue violado? | G1: 2. Un hospital configura su sistema de expedientes para que los médicos solo puedan ver los expedientes de sus propios pacientes, y el personal administrativo solo vea datos de facturación. ¿Qué principio de diseño está aplicando? | H1: 3. ¿Cuál de las siguientes afirmaciones describe correctamente la diferencia entre el modelo perimetral y Zero Trust? | I1: 4. ¿Cuál de los siguientes marcos de seguridad es el único certificable por una auditoría externa? | J1: 5. Un ransomware cifra todos los archivos de una empresa y pide rescate para devolver el acceso. ¿Qué pilar o pilares del CIA Triad fueron afectados? | K1: 6. En el ataque a Uber (2022), el atacante convenció a un empleado de aprobar una solicitud de MFA falsa. Una vez dentro, encontró credenciales de administrador en un script de PowerShell en una carpeta compartida. ¿Qué principio de diseño fue violado al guardar esas credenciales en un lugar accesible para cualquier empleado? | L1: 7. CIS Controls organiza sus 18 controles en tres grupos de implementación. ¿Qué describe correctamente el Grupo IG1? | M1: 8. ¿En qué fase del ciclo de vida de la arquitectura de seguridad se realizan auditorías y pruebas de penetración? | N1: 9. NIST CSF 2.0 agregó una nueva función que no existía en la versión 1.1. ¿Cuál es y qué pregunta responde? | O1: 10. En el ataque a SolarWinds (2020), los atacantes insertaron código malicioso en actualizaciones legítimas del software Orion. ¿Qué fase del ciclo de vida de la arquitectura de seguridad falló principalmente? | P1: 11. Zero Trust es un producto de seguridad que se compra e instala como un firewall. | Q1: 12. El hashing SHA-256 protege principalmente la Integridad de los datos porque genera una huella digital que detecta modificaciones. | R1: 13. NIST CSF es obligatorio para todas las empresas que operan en Estados Unidos. | S1: 14. La defensa en profundidad y la redundancia son lo mismo: ambas duplican controles para mayor seguridad. | T1: 15. Los cinco pilares de Zero Trust según NIST SP 800-207 son: Identidad, Dispositivo, Red, Aplicación y Datos. | U1: 16. En el modelo perimetral, una vez que un atacante cruza el firewall tiene acceso libre a todo el interior de la red. | V1: 17. ISO 27001 impone los mismos controles técnicos específicos a todas las organizaciones sin importar su contexto. | W1: 18. La disponibilidad se viola únicamente cuando hay un ataque intencional como un DDoS, no por fallos de hardware. | X1: 19. CIS Controls v8 tiene una prescripción alta porque te dice exactamente qué hacer, no solo qué lograr. | Y1: 20. El ciclo de vida de la arquitectura de seguridad es un proceso que se ejecuta una sola vez al diseñar el sistema. | Z1: 21. El siguiente escenario combina conceptos de las tres sesiones que tuvimos. Léelo con cuidado y responde lo que se pide. Una startup de tecnología financiera almacena datos de tarjetas de crédito de sus usuarios. Su equipo de desarrollo tiene acceso completo a la base de datos de producción para "agilizar las correcciones de bugs". No tienen ningún marco de seguridad implementado formalmente. Un día, un desarrollador con acceso a producción renuncia molesto y antes de irse descarga 50,000 registros de tarjetas. El incidente no se detecta hasta tres meses después cuando los usuarios reportan cargos no reconocidos. Responde las tres preguntas siguientes en no más de 8 líneas en total: - ¿Qué pilar o pilares del CIA Triad fueron violados y cómo? - ¿Qué principio de diseño habría limitado el daño si hubiera estado implementado desde el inicio? - ¿Qué marco de seguridad le recomendarías a esta empresa como punto de partida y por qué ese específicamente?
A2: 46106.415 | B2: GONZALEZ CUELLAR EDGAR OSWALDO | C2: edgar.gonzalez1780@alumnos.udg.mx | D2: 94 / 110 | E2: =MIN(100,VALUE(TRIM(LEFT(D2,FIND("/",D2)-1)))) -> 94 | F2: c) Solo Confidencialidad | G2: d) Zero Trust | H2: b) Zero Trust asume que nada es confiable por defecto | I2: c) ISO 27001 | J2: b) Integridad y Disponibilidad | K2: b) Mínimo privilegio | L2: c) Higiene básica que toda organización debe implementar y que evita el 85% de los ataques comunes | M2: d) Fase 4 - Verificación y validación | N2: b) GOVERN — ¿Cómo se toman las decisiones de seguridad? | O2: Fase 3 — Implementación sin validación de integridad y Fase 4 — Monitoreo insuficiente | P2: Falso | Q2: Verdadero | R2: Falso | S2: Falso | T2: Verdadero | U2: Falso | V2: Verdadero | W2: Falso | X2: Verdadero | Y2: Falso | Z2: Confidencialidad e integridad , detección y principio del menor privilegio , nist ya que es flexible
A3: 46106.415 | B3: MARTINEZ DURAN MAHONRI MORIANC | C3: mahonri.martinez6831@alumnos.udg.mx | D3: 110 / 110 | E3: =MIN(100,VALUE(TRIM(LEFT(D3,FIND("/",D3)-1)))) -> 100 | F3: c) Solo Confidencialidad | G3: c) Mínimo privilegio | H3: b) Zero Trust asume que nada es confiable por defecto | I3: c) ISO 27001 | J3: b) Integridad y Disponibilidad | K3: b) Mínimo privilegio | L3: c) Higiene básica que toda organización debe implementar y que evita el 85% de los ataques comunes | M3: d) Fase 4 - Verificación y validación | N3: b) GOVERN — ¿Cómo se toman las decisiones de seguridad? | O3: Fase 3 — Implementación sin validación de integridad y Fase 4 — Monitoreo insuficiente | P3: Falso | Q3: Verdadero | R3: Falso | S3: Falso | T3: Verdadero | U3: Verdadero | V3: Falso | W3: Falso | X3: Verdadero | Y3: Falso | Z3: CIA: Se violo la Confidencialidad por el robo de datos y la Integridad Principio: Mínimo Privilegio para que no tuviera acceso si no era necesario Marco: CIS Controls (IG1), o Zero trust ya que al ser datos bancarios son muy delicados , y tienen que estar muy bien organizados y limpios .
A4: 46106.415 | B4: MUÑOZ RIVAS JOSHUA | C4: joshua.munoz6454@alumnos.udg.mx | D4: 100 / 110 | E4: =MIN(100,VALUE(TRIM(LEFT(D4,FIND("/",D4)-1)))) -> 100 | F4: c) Solo Confidencialidad | G4: c) Mínimo privilegio | H4: b) Zero Trust asume que nada es confiable por defecto | I4: c) ISO 27001 | J4: b) Integridad y Disponibilidad | K4: b) Mínimo privilegio | L4: c) Higiene básica que toda organización debe implementar y que evita el 85% de los ataques comunes | M4: d) Fase 4 - Verificación y validación | N4: b) GOVERN — ¿Cómo se toman las decisiones de seguridad? | O4: Fase 3 — Implementación sin validación de integridad y Fase 4 — Monitoreo insuficiente | P4: Falso | Q4: Verdadero | R4: Falso | S4: Falso | T4: Verdadero | U4: Verdadero | V4: Falso | W4: Falso | X4: Verdadero | Y4: Falso | Z4: 1 se violo la confidencialidad y la integridad de forma indirecta al perder el control sobre informacion sensible 2 el principio que habria limitado el daño es el pricipio de minimo privilegio 3 se recomienda CIS controls v8 como un punto de partida bastante bueno ya que es practico, prescriptivo y ayuda con controles basicos
A5: 46106.416 | B5: FREGOSO SANCHEZ PAOLA | C5: paola.fregoso5920@alumnos.udg.mx | D5: 88 / 110 | E5: =MIN(100,VALUE(TRIM(LEFT(D5,FIND("/",D5)-1)))) -> 88 | F5: c) Solo Confidencialidad | G5: c) Mínimo privilegio | H5: b) Zero Trust asume que nada es confiable por defecto | I5: c) ISO 27001 | J5: c) Solo Disponibilidad | K5: c) Segmentación | L5: c) Higiene básica que toda organización debe implementar y que evita el 85% de los ataques comunes | M5: d) Fase 4 - Verificación y validación | N5: b) GOVERN — ¿Cómo se toman las decisiones de seguridad? | O5: Fase 3 — Implementación sin validación de integridad y Fase 4 — Monitoreo insuficiente | P5: Falso | Q5: Verdadero | R5: Falso | S5: Falso | T5: Verdadero | U5: Falso | V5: Verdadero | W5: Falso | X5: Verdadero | Y5: Falso | Z5: 1. La confidencialidad ya que los empleados al ya no formar parte de la empresa, toda información perteneciente a ella ya es confidencial. 2. Que los desarrolladores no tuvieran acceso a la información financiera 3. El NIST ya que brinda instrucciones concretas del diseño de Arquitectura
A6: 46106.417 | B6: LAZOS CRUZ ALLISON | C6: allison.lazos8860@alumnos.udg.mx | D6: 104 / 110 | E6: =MIN(100,VALUE(TRIM(LEFT(D6,FIND("/",D6)-1)))) -> 100 | F6: c) Solo Confidencialidad | G6: c) Mínimo privilegio | H6: b) Zero Trust asume que nada es confiable por defecto | I6: c) ISO 27001 | J6: c) Solo Disponibilidad | K6: b) Mínimo privilegio | L6: c) Higiene básica que toda organización debe implementar y que evita el 85% de los ataques comunes | M6: d) Fase 4 - Verificación y validación | N6: b) GOVERN — ¿Cómo se toman las decisiones de seguridad? | O6: Fase 3 — Implementación sin validación de integridad y Fase 4 — Monitoreo insuficiente | P6: Falso | Q6: Verdadero | R6: Falso | S6: Falso | T6: Verdadero | U6: Verdadero | V6: Falso | W6: Falso | X6: Verdadero | Y6: Falso | Z6: 1. La confidencialidad ya que se descargó sin autorizacion los registros, la integridad al estar el riesgo de manipulacion de datos. 2.Mínimo privilegio habría limitado el daño, pues los desarrolladores no deberían tener acceso directo a la base de datos de producción con información sensible. 3.El ISO 27001, porque ofrece un sistema formal y flexible de gestión de la seguridad de la información.
A7: 46106.417 | B7: FRANCO ARELLANO DAPHNE WENDOLYN | C7: daphne.franco0514@alumnos.udg.mx | D7: 110 / 110 | E7: =MIN(100,VALUE(TRIM(LEFT(D7,FIND("/",D7)-1)))) -> 100 | F7: c) Solo Confidencialidad | G7: c) Mínimo privilegio | H7: b) Zero Trust asume que nada es confiable por defecto | I7: c) ISO 27001 | J7: b) Integridad y Disponibilidad | K7: b) Mínimo privilegio | L7: c) Higiene básica que toda organización debe implementar y que evita el 85% de los ataques comunes | M7: d) Fase 4 - Verificación y validación | N7: b) GOVERN — ¿Cómo se toman las decisiones de seguridad? | O7: Fase 3 — Implementación sin validación de integridad y Fase 4 — Monitoreo insuficiente | P7: Falso | Q7: Verdadero | R7: Falso | S7: Falso | T7: Verdadero | U7: Verdadero | V7: Falso | W7: Falso | X7: Verdadero | Y7: Falso | Z7: Se violó la confidencialidad(los 50,000 registros de tarjetas fueron sustraídos sin autorización) e integridad (por el acceso completo que permitía las modificaciones no autorizadas a los datos. Considero que el principio "mínimo privilegio" habría limitado el daño al restringir acceso del desarrollador para que cada quien tenga solo lo necesario para su función. Como marco de partida recomendaría el CIS Controls v8 porque es altamente prescriptivo y prioriza acciones concretas.
